Workbook

Sheet Assumptions
B1: ASSUMPTIONS — UNDERWRITING MODEL
B3: Property Name | C3: West 35th Street, Austin, Texas
B4: Search ID / Address | C4: SRCH-20260307-005 | 1717, West 35th Street, Military Heights, Austin, Travis County, Texas, 78756, United States
B6: ① ACQUISITION & PROPERTY | F6: ── DEAL SNAPSHOT ──
B7: Acquisition Price ($) | C7: 2400000 | F7: Price / Unit | G7: =IFERROR(C7/C12,"") -> 120000
B8: Closing Costs (%) | C8: 0.02 | F8: CapEx / Unit | G8: =IFERROR(C10/C12,"") -> 12500
B9: Closing Costs ($) | C9: =C7*C8 -> 48000 | F9: Total Investment | G9: =C11 -> 2698000
B10: CapEx / Renovation Budget ($) | C10: 250000
B11: Total Acquisition Cost ($) | C11: =C7+C9+C10 -> 2698000
B12: Total Units | C12: 20
B14: ② UNIT MIX & RENT SCHEDULE (beds/baths drive comp lookup — edit to update)
B15: Unit Type | C15: Beds | D15: Baths | E15: Count | F15: Avg Rent/Mo ($) | G15: Avg SF | H15: Total SF | I15: Total Ann. Rent ($)
B16: 0BR/1BA | C16: 0 | D16: 1 | E16: =IF(B16<>"",IFERROR(C12/COUNTA(B16:B20),0),"") -> 6.6666667 | F16: =IFERROR(AVERAGEIFS('Raw Comps'!$I$4:$I$871,'Raw Comps'!$J$4:$J$871,C16,'Raw Comps'!$K$4:$K$871,D16),"") -> 1172.36 | G16: =IFERROR(AVERAGEIFS('Raw Comps'!$L$4:$L$871,'Raw Comps'!$J$4:$J$871,C16,'Raw Comps'!$K$4:$K$871,D16),"") -> 419.84 | H16: =IFERROR(G16*E16,"") -> 2798.9333 | I16: =IFERROR(F16*E16*12,"") -> 93788.8
B17: 1BR/1BA | C17: 1 | D17: 1 | E17: =IF(B17<>"",IFERROR(C12/COUNTA(B16:B20),0),"") -> 6.6666667 | F17: =IFERROR(AVERAGEIFS('Raw Comps'!$I$4:$I$871,'Raw Comps'!$J$4:$J$871,C17,'Raw Comps'!$K$4:$K$871,D17),"") -> 1369.34 | G17: =IFERROR(AVERAGEIFS('Raw Comps'!$L$4:$L$871,'Raw Comps'!$J$4:$J$871,C17,'Raw Comps'!$K$4:$K$871,D17),"") -> 681.36 | H17: =IFERROR(G17*E17,"") -> 4542.4 | I17: =IFERROR(F17*E17*12,"") -> 109547.2
B18: 2BR/2BA | C18: 2 | D18: 2 | E18: =IF(B18<>"",IFERROR(C12/COUNTA(B16:B20),0),"") -> 6.6666667 | F18: =IFERROR(AVERAGEIFS('Raw Comps'!$I$4:$I$871,'Raw Comps'!$J$4:$J$871,C18,'Raw Comps'!$K$4:$K$871,D18),"") -> 2266.7 | G18: =IFERROR(AVERAGEIFS('Raw Comps'!$L$4:$L$871,'Raw Comps'!$J$4:$J$871,C18,'Raw Comps'!$K$4:$K$871,D18),"") -> 1090.74 | H18: =IFERROR(G18*E18,"") -> 7271.6 | I18: =IFERROR(F18*E18*12,"") -> 181336
B21: TOTALS | E21: =SUM(E16:E20) -> 20 | F21: =IFERROR(SUMPRODUCT(F16:F20,E16:E20)/SUM(E16:E20),"") -> 1602.8 | H21: =SUM(H16:H20) -> 14612.933 | I21: =SUM(I16:I20) -> 384672
B22: Gross Potential Rent / Yr ($) | C22: =I21 -> 384672
B24: ③ REVENUE ASSUMPTIONS
B25: Vacancy & Credit Loss (%) | C25: 0.07
B26: Other Income / Unit / Month ($) | C26: 75
B28: ④ OPERATING EXPENSES
B29: OpEx Ratio (% of EGI) | C29: 0.35
B30: OpEx Growth Rate (%) | C30: 0.03
B32: ⑤ DEBT ASSUMPTIONS
B33: Loan Type | C33: Agency/Perm
B34: LTV (%) | C34: 0.7
B35: Loan Amount ($) | C35: =C7*C34 -> 1680000
B36: Interest Rate (%) | C36: 0.065
B37: IO Period (Months) | C37: 24
B38: Amortization (Years) | C38: 30
B39: Loan Term (Years) | C39: 10
B40: Origination Fee (%) | C40: 0.01
B41: Origination Fee ($) | C41: =C35*C40 -> 16800
B43: ⑥ HOLD PERIOD & EXIT
B44: Hold Period (Years) | C44: 5
B45: Exit Cap Rate (%) | C45: 0.07
B46: Selling Costs (%) | C46: 0.04
B48: ⑦ GP / LP STRUCTURE
B49: GP Co-Invest (%) | C49: 0.1
B50: LP Preferred Return (%) | C50: 0.08
...

Sheet Pro Forma
B2: ANNUAL PRO FORMA CASH FLOW (Year 0–10)
C4: Assumptions | D4: Year 0 | E4: Year 1 | F4: Year 2 | G4: Year 3 | H4: Year 4 | I4: Year 5 | J4: Year 6 | K4: Year 7 | L4: Year 8 | M4: Year 9 | N4: Year 10
B5: REVENUE
B6: Gross Potential Rent | C6: =Assumptions!C22 -> 384672 | D6: =$C$6 -> 384672 | E6: =D6*(1+E7) -> 396212.16 | F6: =E6*(1+F7) -> 408098.52 | G6: =F6*(1+G7) -> 418300.99 | H6: =G6*(1+H7) -> 428758.51 | I6: =H6*(1+I7) -> 439477.48 | J6: =I6*(1+J7) -> 448267.02 | K6: =J6*(1+K7) -> 457232.37 | L6: =K6*(1+L7) -> 466377.01 | ... N6: =M6*(1+N7) -> 485218.64
B7: Rent Growth Rate | E7: =Assumptions!C55 -> 0.03 | F7: =Assumptions!D55 -> 0.03 | G7: =Assumptions!E55 -> 0.025 | H7: =Assumptions!F55 -> 0.025 | I7: =Assumptions!G55 -> 0.025 | J7: =Assumptions!H55 -> 0.02 | K7: =Assumptions!I55 -> 0.02 | L7: =Assumptions!J55 -> 0.02 | ... N7: =Assumptions!L55 -> 0.02
B8: Other Income | C8: =Assumptions!C12*Assumptions!C26*12 -> 18000 | D8: =$C$8 -> 18000 | E8: =D8*(1+E7) -> 18540 | F8: =E8*(1+F7) -> 19096.2 | G8: =F8*(1+G7) -> 19573.605 | H8: =G8*(1+H7) -> 20062.945 | I8: =H8*(1+I7) -> 20564.519 | J8: =I8*(1+J7) -> 20975.809 | K8: =J8*(1+K7) -> 21395.325 | L8: =K8*(1+L7) -> 21823.232 | ... N8: =M8*(1+N7) -> 22704.89
B9: Effective Gross Income (EGI) | D9: =D6+D8 -> 402672 | E9: =E6+E8 -> 414752.16 | F9: =F6+F8 -> 427194.72 | G9: =G6+G8 -> 437874.59 | H9: =H6+H8 -> 448821.46 | I9: =I6+I8 -> 460041.99 | J9: =J6+J8 -> 469242.83 | K9: =K6+K8 -> 478627.69 | ... N9: =N6+N8 -> 507923.53
B10: Less: Vacancy & Credit Loss | C10: =Assumptions!C25 -> 0.07 | D10: =-D9*$C$10 -> -28187.04 | E10: =-E9*$C$10 -> -29032.651 | F10: =-F9*$C$10 -> -29903.631 | G10: =-G9*$C$10 -> -30651.222 | H10: =-H9*$C$10 -> -31417.502 | I10: =-I9*$C$10 -> -32202.94 | J10: =-J9*$C$10 -> -32846.998 | K10: =-K9*$C$10 -> -33503.938 | ... N10: =-N9*$C$10 -> -35554.647
B11: Net Effective Income | D11: =D9+D10 -> 374484.96 | E11: =E9+E10 -> 385719.51 | F11: =F9+F10 -> 397291.09 | G11: =G9+G10 -> 407223.37 | H11: =H9+H10 -> 417403.96 | I11: =I9+I10 -> 427839.05 | J11: =J9+J10 -> 436395.84 | K11: =K9+K10 -> 445123.75 | ... N11: =N9+N10 -> 472368.89
B13: OPERATING EXPENSES
B14: Operating Expenses | C14: =Assumptions!C29 -> 0.35 | D14: =D11*$C$14 -> 131069.74 | E14: =D14*(1+Assumptions!C30) -> 135001.83 | F14: =E14*(1+Assumptions!C30) -> 139051.88 | G14: =F14*(1+Assumptions!C30) -> 143223.44 | H14: =G14*(1+Assumptions!C30) -> 147520.14 | I14: =H14*(1+Assumptions!C30) -> 151945.75 | J14: =I14*(1+Assumptions!C30) -> 156504.12 | K14: =J14*(1+Assumptions!C30) -> 161199.24 | L14: =K14*(1+Assumptions!C30) -> 166035.22 | M14: =L14*(1+Assumptions!C30) -> 171016.28 | N14: =M14*(1+Assumptions!C30) -> 176146.77
B19: Total Operating Expenses | D19: =D14 -> 131069.74 | E19: =E14 -> 135001.83 | F19: =F14 -> 139051.88 | G19: =G14 -> 143223.44 | H19: =H14 -> 147520.14 | I19: =I14 -> 151945.75 | J19: =J14 -> 156504.12 | K19: =K14 -> 161199.24 | ... N19: =N14 -> 176146.77
B21: NET OPERATING INCOME (NOI) | D21: =D11-D19 -> 243415.22 | E21: =E11-E19 -> 250717.68 | F21: =F11-F19 -> 258239.21 | G21: =G11-G19 -> 263999.93 | H21: =H11-H19 -> 269883.81 | I21: =I11-I19 -> 275893.31 | J21: =J11-J19 -> 279891.72 | K21: =K11-K19 -> 283924.51 | ... N21: =N11-N19 -> 296222.12
B23: DEBT SERVICE
B24: Interest Expense | D24: =Assumptions!C35*Assumptions!C36 -> 109200 | E24: =IF(1*12<=Assumptions!C37,Assumptions!C35*Assumptions!C36,IF((1-1)*12>=Assumptions!C37,-CUMIPMT(Assumptions!C36/12,Assumptions!C38*12,Assumptions!C35,(1-1)*12-Assumptions!C37+1,1*12-Assumptions!C37,0),Assumptions!C35*Assumptions!C36*(Assumptions!C37-(1-1)*12)/12+(-CUMIPMT(Assumptions!C36/12,Assumptions!C38*12,Assumptions!C35,1,1*12-Assumptions!C37,0)))) -> 109200 | F24: =IF(2*12<=Assumptions!C37,Assumptions!C35*Assumptions!C36,IF((2-1)*12>=Assumptions!C37,-CUMIPMT(Assumptions!C36/12,Assumptions!C38*12,Assumptions!C35,(2-1)*12-Assumptions!C37+1,2*12-Assumptions!C37,0),Assumptions!C35*Assumptions!C36*(Assumptions!C37-(2-1)*12)/12+(-CUMIPMT(Assumptions!C36/12,Assumptions!C38*12,Assumptions!C35,1,2*12-Assumptions!C37,0)))) -> 109200 | G24: =IF(3*12<=Assumptions!C37,Assumptions!C35*Assumptions!C36,IF((3-1)*12>=Assumptions!C37,-CUMIPMT(Assumptions!C36/12,Assumptions!C38*12,Assumptions!C35,(3-1)*12-Assumptions!C37+1,3*12-Assumptions!C37,0),Assumptions!C35*Assumptions!C36*(Assumptions!C37-(3-1)*12)/12+(-CUMIPMT(Assumptions!C36/12,Assumptions!C38*12,Assumptions!C35,1,3*12-Assumptions!C37,0)))) -> 108647.13 | H24: =IF(4*12<=Assumptions!C37,Assumptions!C35*Assumptions!C36,IF((4-1)*12>=Assumptions!C37,-CUMIPMT(Assumptions!C36/12,Assumptions!C38*12,Assumptions!C35,(4-1)*12-Assumptions!C37+1,4*12-Assumptions!C37,0),Assumptions!C35*Assumptions!C36*(Assumptions!C37-(4-1)*12)/12+(-CUMIPMT(Assumptions!C36/12,Assumptions!C38*12,Assumptions!C35,1,4*12-Assumptions!C37,0)))) -> 107389.54 | I24: =IF(5*12<=Assumptions!C37,Assumptions!C35*Assumptions!C36,IF((5-1)*12>=Assumptions!C37,-CUMIPMT(Assumptions!C36/12,Assumptions!C38*12,Assumptions!C35,(5-1)*12-Assumptions!C37+1,5*12-Assumptions!C37,0),Assumptions!C35*Assumptions!C36*(Assumptions!C37-(5-1)*12)/12+(-CUMIPMT(Assumptions!C36/12,Assumptions!C38*12,Assumptions!C35,1,5*12-Assumptions!C37,0)))) -> 106047.74 | J24: =IF(6*12<=Assumptions!C37,Assumptions!C35*Assumptions!C36,IF((6-1)*12>=Assumptions!C37,-CUMIPMT(Assumptions!C36/12,Assumptions!C38*12,Assumptions!C35,(6-1)*12-Assumptions!C37+1,6*12-Assumptions!C37,0),Assumptions!C35*Assumptions!C36*(Assumptions!C37-(6-1)*12)/12+(-CUMIPMT(Assumptions!C36/12,Assumptions!C38*12,Assumptions!C35,1,6*12-Assumptions!C37,0)))) -> 104616.07 | K24: =IF(7*12<=Assumptions!C37,Assumptions!C35*Assumptions!C36,IF((7-1)*12>=Assumptions!C37,-CUMIPMT(Assumptions!C36/12,Assumptions!C38*12,Assumptions!C35,(7-1)*12-Assumptions!C37+1,7*12-Assumptions!C37,0),Assumptions!C35*Assumptions!C36*(Assumptions!C37-(7-1)*12)/12+(-CUMIPMT(Assumptions!C36/12,Assumptions!C38*12,Assumptions!C35,1,7*12-Assumptions!C37,0)))) -> 103088.52 | L24: =IF(8*12<=Assumptions!C37,Assumptions!C35*Assumptions!C36,IF((8-1)*12>=Assumptions!C37,-CUMIPMT(Assumptions!C36/12,Assumptions!C38*12,Assumptions!C35,(8-1)*12-Assumptions!C37+1,8*12-Assumptions!C37,0),Assumptions!C35*Assumptions!C36*(Assumptions!C37-(8-1)*12)/12+(-CUMIPMT(Assumptions!C36/12,Assumptions!C38*12,Assumptions!C35,1,8*12-Assumptions!C37,0)))) -> 101458.66 | M24: =IF(9*12<=Assumptions!C37,Assumptions!C35*Assumptions!C36,IF((9-1)*12>=Assumptions!C37,-CUMIPMT(Assumptions!C36/12,Assumptions!C38*12,Assumptions!C35,(9-1)*12-Assumptions!C37+1,9*12-Assumptions!C37,0),Assumptions!C35*Assumptions!C36*(Assumptions!C37-(9-1)*12)/12+(-CUMIPMT(Assumptions!C36/12,Assumptions!C38*12,Assumptions!C35,1,9*12-Assumptions!C37,0)))) -> 99719.655 | N24: =IF(10*12<=Assumptions!C37,Assumptions!C35*Assumptions!C36,IF((10-1)*12>=Assumptions!C37,-CUMIPMT(Assumptions!C36/12,Assumptions!C38*12,Assumptions!C35,(10-1)*12-Assumptions!C37+1,10*12-Assumptions!C37,0),Assumptions!C35*Assumptions!C36*(Assumptions!C37-(10-1)*12)/12+(-CUMIPMT(Assumptions!C36/12,Assumptions!C38*12,Assumptions!C35,1,10*12-Assumptions!C37,0)))) -> 97864.183
B25: Principal Payment | D25: =0 -> 0 | E25: =IF(1*12<=Assumptions!C37,0,IF((1-1)*12>=Assumptions!C37,-CUMPRINC(Assumptions!C36/12,Assumptions!C38*12,Assumptions!C35,(1-1)*12-Assumptions!C37+1,1*12-Assumptions!C37,0),-CUMPRINC(Assumptions!C36/12,Assumptions!C38*12,Assumptions!C35,1,1*12-Assumptions!C37,0))) -> 0 | F25: =IF(2*12<=Assumptions!C37,0,IF((2-1)*12>=Assumptions!C37,-CUMPRINC(Assumptions!C36/12,Assumptions!C38*12,Assumptions!C35,(2-1)*12-Assumptions!C37+1,2*12-Assumptions!C37,0),-CUMPRINC(Assumptions!C36/12,Assumptions!C38*12,Assumptions!C35,1,2*12-Assumptions!C37,0))) -> 0 | G25: =IF(3*12<=Assumptions!C37,0,IF((3-1)*12>=Assumptions!C37,-CUMPRINC(Assumptions!C36/12,Assumptions!C38*12,Assumptions!C35,(3-1)*12-Assumptions!C37+1,3*12-Assumptions!C37,0),-CUMPRINC(Assumptions!C36/12,Assumptions!C38*12,Assumptions!C35,1,3*12-Assumptions!C37,0))) -> 18777.788 | H25: =IF(4*12<=Assumptions!C37,0,IF((4-1)*12>=Assumptions!C37,-CUMPRINC(Assumptions!C36/12,Assumptions!C38*12,Assumptions!C35,(4-1)*12-Assumptions!C37+1,4*12-Assumptions!C37,0),-CUMPRINC(Assumptions!C36/12,Assumptions!C38*12,Assumptions!C35,1,4*12-Assumptions!C37,0))) -> 20035.371 | I25: =IF(5*12<=Assumptions!C37,0,IF((5-1)*12>=Assumptions!C37,-CUMPRINC(Assumptions!C36/12,Assumptions!C38*12,Assumptions!C35,(5-1)*12-Assumptions!C37+1,5*12-Assumptions!C37,0),-CUMPRINC(Assumptions!C36/12,Assumptions!C38*12,Assumptions!C35,1,5*12-Assumptions!C37,0))) -> 21377.177 | J25: =IF(6*12<=Assumptions!C37,0,IF((6-1)*12>=Assumptions!C37,-CUMPRINC(Assumptions!C36/12,Assumptions!C38*12,Assumptions!C35,(6-1)*12-Assumptions!C37+1,6*12-Assumptions!C37,0),-CUMPRINC(Assumptions!C36/12,Assumptions!C38*12,Assumptions!C35,1,6*12-Assumptions!C37,0))) -> 22808.846 | K25: =IF(7*12<=Assumptions!C37,0,IF((7-1)*12>=Assumptions!C37,-CUMPRINC(Assumptions!C36/12,Assumptions!C38*12,Assumptions!C35,(7-1)*12-Assumptions!C37+1,7*12-Assumptions!C37,0),-CUMPRINC(Assumptions!C36/12,Assumptions!C38*12,Assumptions!C35,1,7*12-Assumptions!C37,0))) -> 24336.397 | L25: =IF(8*12<=Assumptions!C37,0,IF((8-1)*12>=Assumptions!C37,-CUMPRINC(Assumptions!C36/12,Assumptions!C38*12,Assumptions!C35,(8-1)*12-Assumptions!C37+1,8*12-Assumptions!C37,0),-CUMPRINC(Assumptions!C36/12,Assumptions!C38*12,Assumptions!C35,1,8*12-Assumptions!C37,0))) -> 25966.25 | M25: =IF(9*12<=Assumptions!C37,0,IF((9-1)*12>=Assumptions!C37,-CUMPRINC(Assumptions!C36/12,Assumptions!C38*12,Assumptions!C35,(9-1)*12-Assumptions!C37+1,9*12-Assumptions!C37,0),-CUMPRINC(Assumptions!C36/12,Assumptions!C38*12,Assumptions!C35,1,9*12-Assumptions!C37,0))) -> 27705.258 | N25: =IF(10*12<=Assumptions!C37,0,IF((10-1)*12>=Assumptions!C37,-CUMPRINC(Assumptions!C36/12,Assumptions!C38*12,Assumptions!C35,(10-1)*12-Assumptions!C37+1,10*12-Assumptions!C37,0),-CUMPRINC(Assumptions!C36/12,Assumptions!C38*12,Assumptions!C35,1,10*12-Assumptions!C37,0))) -> 29560.731
B26: Total Debt Service | D26: =D24+D25 -> 109200 | E26: =E24+E25 -> 109200 | F26: =F24+F25 -> 109200 | G26: =G24+G25 -> 127424.91 | H26: =H24+H25 -> 127424.91 | I26: =I24+I25 -> 127424.91 | J26: =J24+J25 -> 127424.91 | K26: =K24+K25 -> 127424.91 | ... N26: =N24+N25 -> 127424.91
B28: CASH FLOW BEFORE TAX | D28: =D21-D26 -> 134215.22 | E28: =E21-E26 -> 141517.68 | F28: =F21-F26 -> 149039.21 | G28: =G21-G26 -> 136575.02 | H28: =H21-H26 -> 142458.9 | I28: =I21-I26 -> 148468.39 | J28: =J21-J26 -> 152466.8 | K28: =K21-K26 -> 156499.6 | ... N28: =N21-N26 -> 168797.21
B29: Cumulative Cash Flow | D29: =D28 -> 134215.22 | E29: =D29+E28 -> 275732.9 | F29: =E29+F28 -> 424772.12 | G29: =F29+G28 -> 561347.13 | H29: =G29+H28 -> 703806.03 | I29: =H29+I28 -> 852274.43 | J29: =I29+J28 -> 1004741.2 | K29: =J29+K28 -> 1161240.8 | L29: =K29+L28 -> 1321806.9 | ... N29: =M29+N28 -> 1655269.7
B31: KEY METRICS
B32: DSCR | D32: =D21/D26 -> 2.2290771 | E32: =E21/E26 -> 2.2959495 | F32: =F21/F26 -> 2.3648279 | G32: =G21/G26 -> 2.0718078 | H32: =H21/H26 -> 2.1179831 | I32: =I21/I26 -> 2.1651442 | J32: =J21/J26 -> 2.1965227 | K32: =K21/K26 -> 2.2281711 | ... N32: =N21/N26 -> 2.3246798
B33: Cash-on-Cash Return | D33: =D28/Assumptions!C58 -> 0.12970161 | E33: =E28/Assumptions!C58 -> 0.13675849 | F33: =F28/Assumptions!C58 -> 0.14402707 | G33: =G28/Assumptions!C58 -> 0.13198204 | H33: =H28/Assumptions!C58 -> 0.13766805 | I33: =I28/Assumptions!C58 -> 0.14347545 | J33: =J28/Assumptions!C58 -> 0.14733939 | K33: =K28/Assumptions!C58 -> 0.15123656 | L33: =L28/Assumptions!C58 -> 0.15516631 | M33: =M28/Assumptions!C58 -> 0.15912791 | N33: =N28/Assumptions!C58 -> 0.16312061
B34: Cap Rate (on Purchase) | D34: =D21/Assumptions!C7 -> 0.10142301 | E34: =E21/Assumptions!C7 -> 0.1044657 | F34: =F21/Assumptions!C7 -> 0.10759967 | G34: =G21/Assumptions!C7 -> 0.10999997 | H34: =H21/Assumptions!C7 -> 0.11245159 | I34: =I21/Assumptions!C7 -> 0.11495554 | J34: =J21/Assumptions!C7 -> 0.11662155 | K34: =K21/Assumptions!C7 -> 0.11830188 | L34: =L21/Assumptions!C7 -> 0.11999625 | M34: =M21/Assumptions!C7 -> 0.12170436 | N34: =N21/Assumptions!C7 -> 0.12342588
B35: OpEx Ratio | D35: =D19/D11 -> 0.35 | E35: =E19/E11 -> 0.35 | F35: =F19/F11 -> 0.35 | G35: =G19/G11 -> 0.35170732 | H35: =H19/H11 -> 0.35342296 | I35: =I19/I11 -> 0.35514698 | J35: =J19/J11 -> 0.35862881 | K35: =K19/K11 -> 0.36214478 | ... N35: =N19/N11 -> 0.37290086
B36: All inputs sourced from Assumptions tab — edit blue cells there to update the model.
B38: RETURNS ANALYSIS
B40: EXIT ANALYSIS
B41: Hold Period (Years) | C41: =Assumptions!C44 -> 5
B42: Exit Cap Rate (%) | C42: =Assumptions!C45 -> 0.07
B43: Selling Costs (%) | C43: =Assumptions!C46 -> 0.04
B44: Exit Year NOI ($) | C44: {=INDEX('Pro Forma'!E21:N21,1,Assumptions!C44)} -> 275893.31
B45: Gross Sale Price ($) | C45: =C44/C42 -> 3941333
B46: Less: Selling Costs ($) | C46: =-C45*C43 -> -157653.32
B47: Net Sale Proceeds ($) | C47: =C45+C46 -> 3783679.6
B48: Less: Loan Payoff ($) | C48: =-IF(C41*12<=Assumptions!C37,Assumptions!C35,Assumptions!C35-CUMPRINC(Assumptions!C36/12,Assumptions!C38*12,Assumptions!C35,1,MIN(C41*12-Assumptions!C37,Assumptions!C38*12),0)) -> -1740190.3
B49: Net Equity Proceeds ($) | C49: =C47+C48 -> 2043489.3
B50: Total Equity Invested ($) | C50: =Assumptions!C58 -> 1034800
B52: LEVERED IRR CALCULATION
D53: Year 0 | E53: Year 1 | F53: Year 2 | G53: Year 3 | H53: Year 4 | I53: Year 5 | J53: Year 6 | K53: Year 7 | L53: Year 8 | M53: Year 9 | N53: Year 10
B54: Levered Cash Flows ($) | D54: =-C50 -> -1034800 | E54: =IF(1<=$C$41,'Pro Forma'!E28+IF(1=$C$41,$C$49,0),0) -> 141517.68 | F54: =IF(2<=$C$41,'Pro Forma'!F28+IF(2=$C$41,$C$49,0),0) -> 149039.21 | G54: =IF(3<=$C$41,'Pro Forma'!G28+IF(3=$C$41,$C$49,0),0) -> 136575.02 | H54: =IF(4<=$C$41,'Pro Forma'!H28+IF(4=$C$41,$C$49,0),0) -> 142458.9 | I54: =IF(5<=$C$41,'Pro Forma'!I28+IF(5=$C$41,$C$49,0),0) -> 2191957.7 | J54: =IF(6<=$C$41,'Pro Forma'!J28+IF(6=$C$41,$C$49,0),0) -> 0 | K54: =IF(7<=$C$41,'Pro Forma'!K28+IF(7=$C$41,$C$49,0),0) -> 0 | L54: =IF(8<=$C$41,'Pro Forma'!L28+IF(8=$C$41,$C$49,0),0) -> 0 | M54: =IF(9<=$C$41,'Pro Forma'!M28+IF(9=$C$41,$C$49,0),0) -> 0 | N54: =IF(10<=$C$41,'Pro Forma'!N28+IF(10=$C$41,$C$49,0),0) -> 0
...

Sheet Returns
B1: ⚠ Returns data has been consolidated onto the Pro Forma sheet. This sheet is kept for historical reference only.
B2: EXIT & RETURNS ANALYSIS
B3: All inputs auto-populated from Assumptions tab | Edit blue cells on Assumptions to update this model
B5: LEVERED RETURN SUMMARY | E5: UNLEVERED RETURN SUMMARY
B6: Metric | C6: Value | E6: Metric | F6: Value
B7: Levered IRR | C7: ='Pro Forma'!C57 -> 0.25593797 | E7: Unlevered IRR | F7: ='Pro Forma'!C67 -> 0.15606395
B8: Equity Multiple (MOIC) | C8: ='Pro Forma'!C58 -> 2.6686785 | E8: Equity Multiple (MOIC) | F8: ='Pro Forma'!C68 -> 1.8911837
B9: Avg Cash-on-Cash Yield | C9: ='Pro Forma'!C59 -> 0.13878222 | E9: Avg NOI Yield on Cost | F9: =AVERAGE('Pro Forma'!E33:INDEX('Pro Forma'!E33:N33,1,'Pro Forma'!C41)) -> 0.13878222
B10: Total Equity Invested ($) | C10: ='Pro Forma'!C50 -> 1034800 | E10: Total Cost ($) | F10: ='Pro Forma'!C69 -> 2698000
B11: Total Profit ($) | C11: ='Pro Forma'!C60 -> 1008689.3 | E11: Total Profit ($) | F11: ='Pro Forma'!C74 -> 1726748.5
B12: LP MOIC | C12: ='Pro Forma'!C80 -> 2.5721587 | E12: Unlevered MOIC | F12: ='Pro Forma'!C68 -> 1.8911837
B14: CASH-ON-CASH RETURN & EQUITY MULTIPLE DECOMPOSITION
B15: Year | D15: 1 | E15: 2 | F15: 3 | G15: 4 | H15: 5 | I15: 6 | J15: 7 | K15: 8 | L15: 9 | M15: 10 | N15: Avg / Total
B16: Cash Flow Before Tax (CFBT) | C16: ='Pro Forma'!D28 -> 134215.22 | D16: ='Pro Forma'!E28 -> 141517.68 | E16: ='Pro Forma'!F28 -> 149039.21 | F16: ='Pro Forma'!G28 -> 136575.02 | G16: ='Pro Forma'!H28 -> 142458.9 | H16: ='Pro Forma'!I28 -> 148468.39 | I16: ='Pro Forma'!J28 -> 152466.8 | J16: ='Pro Forma'!K28 -> 156499.6 | ... M16: ='Pro Forma'!N28 -> 168797.21 | N16: =AVERAGE(D16:M16) -> 152105.45
B17: Cash-on-Cash Yield (%) | C17: n/a | D17: =D16/'Pro Forma'!C50 -> 0.13675849 | E17: =E16/'Pro Forma'!C50 -> 0.14402707 | F17: =F16/'Pro Forma'!C50 -> 0.13198204 | G17: =G16/'Pro Forma'!C50 -> 0.13766805 | H17: =H16/'Pro Forma'!C50 -> 0.14347545 | I17: =I16/'Pro Forma'!C50 -> 0.14733939 | J17: =J16/'Pro Forma'!C50 -> 0.15123656 | K17: =K16/'Pro Forma'!C50 -> 0.15516631 | L17: =L16/'Pro Forma'!C50 -> 0.15912791 | M17: =M16/'Pro Forma'!C50 -> 0.16312061 | N17: =AVERAGE(D17:INDEX(D17:M17,1,'Pro Forma'!C41)) -> 0.13878222
B18: NOI ($) | C18: ='Pro Forma'!D21 -> 243415.22 | D18: ='Pro Forma'!E21 -> 250717.68 | E18: ='Pro Forma'!F21 -> 258239.21 | F18: ='Pro Forma'!G21 -> 263999.93 | G18: ='Pro Forma'!H21 -> 269883.81 | H18: ='Pro Forma'!I21 -> 275893.31 | I18: ='Pro Forma'!J21 -> 279891.72 | J18: ='Pro Forma'!K21 -> 283924.51 | ... M18: ='Pro Forma'!N21 -> 296222.12 | N18: =AVERAGE(D18:M18) -> 275885.38
B19: NOI Yield on Cost (%) | C19: n/a | D19: =D18/'Pro Forma'!C69 -> 0.092927235 | E19: =E18/'Pro Forma'!C69 -> 0.095715052 | F19: =F18/'Pro Forma'!C69 -> 0.097850234 | G19: =G18/'Pro Forma'!C69 -> 0.10003106 | H19: =H18/'Pro Forma'!C69 -> 0.10225845 | I19: =I18/'Pro Forma'!C69 -> 0.10374044 | J19: =J18/'Pro Forma'!C69 -> 0.10523518 | K19: =K18/'Pro Forma'!C69 -> 0.1067424 | L19: =L18/'Pro Forma'!C69 -> 0.10826185 | M19: =M18/'Pro Forma'!C69 -> 0.10979323 | N19: =AVERAGE(D19:M19) -> 0.10225551
B20: DSCR | C20: n/a | D20: ='Pro Forma'!E32 -> 2.2959495 | E20: ='Pro Forma'!F32 -> 2.3648279 | F20: ='Pro Forma'!G32 -> 2.0718078 | G20: ='Pro Forma'!H32 -> 2.1179831 | H20: ='Pro Forma'!I32 -> 2.1651442 | I20: ='Pro Forma'!J32 -> 2.1965227 | J20: ='Pro Forma'!K32 -> 2.2281711 | K20: ='Pro Forma'!L32 -> 2.260084 | ... M20: ='Pro Forma'!N32 -> 2.3246798 | N20: =AVERAGE(D20:M20) -> 2.2317426
B21: Cumulative Equity Multiple | C21: — | D21: =SUM(D16:D16)/'Pro Forma'!C50 -> 0.13675849 | E21: =SUM(D16:E16)/'Pro Forma'!C50 -> 0.28078555 | F21: =SUM(D16:F16)/'Pro Forma'!C50 -> 0.4127676 | G21: =SUM(D16:G16)/'Pro Forma'!C50 -> 0.55043565 | H21: =SUM(D16:H16)/'Pro Forma'!C50 -> 0.6939111 | I21: =SUM(D16:I16)/'Pro Forma'!C50 -> 0.84125049 | J21: =SUM(D16:J16)/'Pro Forma'!C50 -> 0.99248705 | K21: =SUM(D16:K16)/'Pro Forma'!C50 -> 1.1476534 | L21: =SUM(D16:L16)/'Pro Forma'!C50 -> 1.3067813 | M21: =SUM(D16:M16)/'Pro Forma'!C50 -> 1.4699019 | N21: ='Pro Forma'!C58 -> 2.6686785
B22: % of Return from Exit Proceeds | D22: =IF(1='Pro Forma'!$C$41,'Pro Forma'!C49/(D16+'Pro Forma'!C49),0) -> 0 | E22: =IF(2='Pro Forma'!$C$41,'Pro Forma'!C49/(E16+'Pro Forma'!C49),0) -> 0 | F22: =IF(3='Pro Forma'!$C$41,'Pro Forma'!C49/(F16+'Pro Forma'!C49),0) -> 0 | G22: =IF(4='Pro Forma'!$C$41,'Pro Forma'!C49/(G16+'Pro Forma'!C49),0) -> 0 | H22: =IF(5='Pro Forma'!$C$41,'Pro Forma'!C49/(H16+'Pro Forma'!C49),0) -> 0.93226676 | I22: =IF(6='Pro Forma'!$C$41,'Pro Forma'!C49/(I16+'Pro Forma'!C49),0) -> 0 | J22: =IF(7='Pro Forma'!$C$41,'Pro Forma'!C49/(J16+'Pro Forma'!C49),0) -> 0 | K22: =IF(8='Pro Forma'!$C$41,'Pro Forma'!C49/(K16+'Pro Forma'!C49),0) -> 0 | L22: =IF(9='Pro Forma'!$C$41,'Pro Forma'!C49/(L16+'Pro Forma'!C49),0) -> 0 | M22: =IF(10='Pro Forma'!$C$41,'Pro Forma'!C49/(M16+'Pro Forma'!C49),0) -> 0 | N22: ='Pro Forma'!C49/SUM('Pro Forma'!E54:N54) -> 0.73997951
B24: STAKEHOLDER RETURNS
B25: Total Equity Invested ($) | C25: ='Pro Forma'!C50 -> 1034800
B26: Total Distributions (CF + Exit) | C26: ='Pro Forma'!C73 -> 2761548.5
B27: Total Profit | C27: ='Pro Forma'!C74 -> 1726748.5
B28: LP Pref Return (cumulative, simple) | C28: ='Pro Forma'!C75 -> 413920 | D28: ← Simple pref on total equity (see note)
B29: Profit Above Pref | C29: ='Pro Forma'!C76 -> 1312828.5
B30: GP Promote (20% of profit above pref) | C30: ='Pro Forma'!C77 -> 262565.7 | D30: ← No catch-up tier (see note)
B31: GP Total (Co-Invest ROC + Promote) | C31: ='Pro Forma'!C78 -> 366045.7 | D31: ← Excl. GP pro-rata operating CFs (see note)
B32: LP Total (Distributions - GP) | C32: ='Pro Forma'!C79 -> 2395502.8
B33: LP MOIC (LP Total / LP Equity) | C33: ='Pro Forma'!C80 -> 2.5721587
B36: PRICING SCENARIOS — CAP RATE-BASED ACQUISITION ANALYSIS
B38: SENSITIVITY: LEVERED IRR — Entry Cap Rate (rows) × Exit Cap Rate (columns)
B39: Entry Cap \ Exit Cap | C39: Total Cost ($) | D39: 0.05 | E39: 0.055 | F39: 6.0% ★ | G39: 0.065 | H39: 0.07 | I39: 0.075 | J39: 0.08
B40: 0.05 | C40: =F73 -> 5364640.7 | D40: =IFERROR(IRR(B88:G88),"n/a") -> 0.013068216 | E40: =IFERROR(IRR(B89:G89),"n/a") -> -0.04313011 | F40: =IFERROR(IRR(B90:G90),"n/a") -> -0.10291802 | G40: =IFERROR(IRR(B91:G91),"n/a") -> -0.17023835 | H40: =IFERROR(IRR(B92:G92),"n/a") -> -0.25345406 | I40: =IFERROR(IRR(B93:G93),"n/a") -> -0.38090692 | J40: =IFERROR(IRR(B94:G94),"n/a") -> n/a
B41: 0.06 | C41: =F74 -> 4512200.6 | D41: =IFERROR(IRR(B95:G95),"n/a") -> 0.12266863 | E41: =IFERROR(IRR(B96:G96),"n/a") -> 0.078669488 | F41: =IFERROR(IRR(B97:G97),"n/a") -> 0.035345011 | G41: =IFERROR(IRR(B98:G98),"n/a") -> -0.008264887 | H41: =IFERROR(IRR(B99:G99),"n/a") -> -0.053260267 | I41: =IFERROR(IRR(B100:G100),"n/a") -> -0.10110252 | J41: =IFERROR(IRR(B101:G101),"n/a") -> -0.15406477
B42: 0.07 | C42: =F75 -> 3903314.8 | D42: =IFERROR(IRR(B102:G102),"n/a") -> 0.2030196 | E42: =IFERROR(IRR(B103:G103),"n/a") -> 0.16441875 | F42: =IFERROR(IRR(B104:G104),"n/a") -> 0.12758112 | G42: =IFERROR(IRR(B105:G105),"n/a") -> 0.091903024 | H42: =IFERROR(IRR(B106:G106),"n/a") -> 0.056845062 | I42: =IFERROR(IRR(B107:G107),"n/a") -> 0.021883145 | J42: =IFERROR(IRR(B108:G108),"n/a") -> -0.013541557
B43: 0.08 | C43: =F76 -> 3446650.4 | D43: =IFERROR(IRR(B109:G109),"n/a") -> 0.26717316 | E43: =IFERROR(IRR(B110:G110),"n/a") -> 0.23160076 | F43: =IFERROR(IRR(B111:G111),"n/a") -> 0.19822686 | G43: =IFERROR(IRR(B112:G112),"n/a") -> 0.1665321 | H43: =IFERROR(IRR(B113:G113),"n/a") -> 0.13609399 | I43: =IFERROR(IRR(B114:G114),"n/a") -> 0.10655251 | J43: =IFERROR(IRR(B115:G115),"n/a") -> 0.077584535
B44: 0.09 | C44: =F77 -> 3091467 | D44: =IFERROR(IRR(B116:G116),"n/a") -> 0.32084554 | E44: =IFERROR(IRR(B117:G117),"n/a") -> 0.28720126 | F44: =IFERROR(IRR(B118:G118),"n/a") -> 0.25597443 | G44: =IFERROR(IRR(B119:G119),"n/a") -> 0.22667126 | H44: =IFERROR(IRR(B120:G120),"n/a") -> 0.1989039 | I44: =IFERROR(IRR(B121:G121),"n/a") -> 0.17235794 | J44: =IFERROR(IRR(B122:G122),"n/a") -> 0.14677032
B45: 0.1 | C45: =F78 -> 2807320.3 | D45: =IFERROR(IRR(B123:G123),"n/a") -> 0.36709823 | E45: =IFERROR(IRR(B124:G124),"n/a") -> 0.33478388 | F45: =IFERROR(IRR(B125:G125),"n/a") -> 0.30501412 | G45: =IFERROR(IRR(B126:G126),"n/a") -> 0.27730311 | H45: =IFERROR(IRR(B127:G127),"n/a") -> 0.25127462 | I45: =IFERROR(IRR(B128:G128),"n/a") -> 0.22662972 | J45: =IFERROR(IRR(B129:G129),"n/a") -> 0.2031252
B46: 0.11 | C46: =F79 -> 2574836.7 | D46: =IFERROR(IRR(B130:G130),"n/a") -> 0.40778064 | E46: =IFERROR(IRR(B131:G131),"n/a") -> 0.37643632 | F46: =IFERROR(IRR(B132:G132),"n/a") -> 0.34771816 | G46: =IFERROR(IRR(B133:G133),"n/a") -> 0.32114193 | H46: =IFERROR(IRR(B134:G134),"n/a") -> 0.29633499 | I46: =IFERROR(IRR(B135:G135),"n/a") -> 0.27300391 | J46: =IFERROR(IRR(B136:G136),"n/a") -> 0.25091279
...

Sheet Raw Comps
B2: RAW RENT COMPS — COMPARABLE LISTINGS
B3: Populated automatically on import. Cols I/J/K/L (★) drive Rent Assumptions AVERAGEIFS — do not reorder.
B4: # | C4: Purchase Price | D4: Improvements | E4: Rank | F4: Dist (m) | G4: Dist (km) | H4: Unit Type | I4: Rent / Mo ★ | J4: Beds ★ | K4: Baths ★ | L4: Sq Ft ★ | M4: Bedrooms | N4: Bathrooms | O4: Address | P4: Property Type | Q4: Status | R4: DOM | S4: Latitude | T4: Longitude | U4: URL | V4: Listing ID
B5: 1 | C5: 2400000 | D5: 250000 | E5: 1 | F5: 111.4 | G5: 0.111 | H5: Studio | I5: 1050 | J5: 0 | K5: 1 | L5: 550 | M5: 0 | N5: 1 | O5: 1808 W 35th St, Apt 15, Austin, TX 78703 | P5: Apartment | Q5: Active | R5: 1 | S5: 30.308552 | T5: -97.753288 | V5: 1808-W-35th-St,-Apt-15,-Austin,-TX-78703
B6: 2 | C6: 2400000 | D6: 250000 | E6: 2 | F6: 1760.1 | G6: 1.76 | H6: Studio | I6: 900 | J6: 0 | K6: 1 | L6: 400 | M6: 0 | N6: 1 | O6: 305 W 35th St, Apt 113, Austin, TX 78705 | P6: Condo | Q6: Active | R6: 1 | S6: 30.299807 | T6: -97.736801 | V6: 305-W-35th-St,-Apt-113,-Austin,-TX-78705
B7: 3 | C7: 2400000 | D7: 250000 | E7: 3 | F7: 1780 | G7: 1.78 | H7: Studio | I7: 1000 | J7: 0 | K7: 1 | L7: 525 | M7: 0 | N7: 1 | O7: 2704 San Pedro St, Austin, TX 78705 | P7: Condo | Q7: Active | R7: 1 | S7: 30.292707 | T7: -97.746167 | V7: 2704-San-Pedro-St,-Austin,-TX-78705
B8: 4 | C8: 2400000 | D8: 250000 | E8: 4 | F8: 1823.1 | G8: 1.823 | H8: Studio | I8: 900 | J8: 0 | K8: 1 | L8: 390 | M8: 0 | N8: 1 | O8: 210 W 38th St, Apt 5, Austin, TX 78705 | P8: Apartment | Q8: Active | R8: 1 | S8: 30.301765 | T8: -97.734993 | V8: 210-W-38th-St,-Apt-5,-Austin,-TX-78705
B9: 5 | C9: 2400000 | D9: 250000 | E9: 5 | F9: 2019.1 | G9: 2.019 | H9: Studio | I9: 1295 | J9: 0 | K9: 1 | L9: 400 | M9: 0 | N9: 1 | O9: 2505 San Gabriel St, Apt 102, Austin, TX 78705 | P9: Condo | Q9: Active | R9: 1 | S9: 30.290114 | T9: -97.747407 | V9: 2505-San-Gabriel-St,-Apt-102,-Austin,-TX-78705
B10: 6 | C10: 2400000 | D10: 250000 | E10: 6 | F10: 2053.8 | G10: 2.054 | H10: Studio | I10: 925 | J10: 0 | K10: 1 | L10: 500 | M10: 0 | N10: 1 | O10: 709 W 26th St, Apt 15, Austin, TX 78705 | P10: Condo | Q10: Active | R10: 1 | S10: 30.29038 | T10: -97.745232 | V10: 709-W-26th-St,-Apt-15,-Austin,-TX-78705
B11: 7 | C11: 2400000 | D11: 250000 | E11: 7 | F11: 2119.8 | G11: 2.12 | H11: Studio | I11: 800 | J11: 0 | K11: 1 | L11: 500 | M11: 0 | N11: 1 | O11: 202 E 32nd St, Apt 3, Austin, TX 78705 | P11: Apartment | Q11: Active | R11: 1 | S11: 30.296143 | T11: -97.73513 | V11: 202-E-32nd-St,-Apt-3,-Austin,-TX-78705
B12: 8 | C12: 2400000 | D12: 250000 | E12: 8 | F12: 2127.2 | G12: 2.127 | H12: Studio | I12: 1200 | J12: 0 | K12: 1 | L12: 550 | M12: 0 | N12: 1 | O12: 2529 Rio Grande St, Apt 61, Austin, TX 78705 | P12: Condo | Q12: Active | R12: 1 | S12: 30.290072 | T12: -97.74406 | V12: 2529-Rio-Grande-St,-Apt-61,-Austin,-TX-78705
B13: 9 | C13: 2400000 | D13: 250000 | E13: 9 | F13: 2259.7 | G13: 2.26 | H13: Studio | I13: 1500 | J13: 0 | K13: 1 | L13: 350 | M13: 0 | N13: 1 | O13: 2302 Leon St, Apt 1, Austin, TX 78705 | P13: Condo | Q13: Active | R13: 1 | S13: 30.287523 | T13: -97.749781 | V13: 2302-Leon-St,-Apt-1,-Austin,-TX-78705
B14: 10 | C14: 2400000 | D14: 250000 | E14: 10 | F14: 2261.3 | G14: 2.261 | H14: Studio | I14: 1500 | J14: 0 | K14: 1 | L14: 350 | M14: 0 | N14: 1 | O14: 2302 Leon St, Apt 6, Austin, TX 78705 | P14: Single Family | Q14: Active | R14: 1 | S14: 30.287508 | T14: -97.749781 | V14: 2302-Leon-St,-Apt-6,-Austin,-TX-78705
B15: 11 | C15: 2400000 | D15: 250000 | E15: 11 | F15: 2261.3 | G15: 2.261 | H15: Studio | I15: 1500 | J15: 0 | K15: 1 | L15: 350 | M15: 0 | N15: 1 | O15: 2302 Leon St, Apt 3, Austin, TX 78705 | P15: Single Family | Q15: Active | R15: 1 | S15: 30.287508 | T15: -97.749781 | V15: 2302-Leon-St,-Apt-3,-Austin,-TX-78705
B16: 12 | C16: 2400000 | D16: 250000 | E16: 12 | F16: 2261.3 | G16: 2.261 | H16: Studio | I16: 1500 | J16: 0 | K16: 1 | L16: 350 | M16: 0 | N16: 1 | O16: 2302 Leon St, Apt 4, Austin, TX 78705 | P16: Single Family | Q16: Active | R16: 1 | S16: 30.287508 | T16: -97.749781 | V16: 2302-Leon-St,-Apt-4,-Austin,-TX-78705
... B154: 150 | C154: 2400000 | D154: 250000 | E154: 50 | F154: 14098.4 | G154: 14.098 | H154: Duplex | I154: 1400 | J154: 2 | K154: 2 | L154: 1056 | M154: 2 | N154: 2 | O154: 5005 E Parmer Ln, Unit 02-252, Austin, TX 78754 | P154: Condo | Q154: Active | R154: 1 | S154: 30.369854 | T154: -97.624664 | V154: 5005-E-Parmer-Ln,-Unit-02-252,-Austin,-TX-78754

Sheet Debt Schedule
B2: DEBT AMORTIZATION SCHEDULE
B4: KEY INPUTS
B5: Loan Amount ($) | C5: =Assumptions!C35 -> 1680000
B6: Annual Interest Rate | C6: =Assumptions!C36 -> 0.065
B7: IO Period (Months) | C7: =Assumptions!C37 -> 24
B8: Amortization (Years) | C8: =Assumptions!C38 -> 30
B9: Monthly Rate | C9: =C6/12 -> 0.0054166667
B10: Monthly Payment (Amort) | C10: =-PMT(C6/12,C8*12,C5) -> 10618.743
B12: Month | C12: Year | D12: IO/Amort | E12: Beg Balance | F12: Payment | G12: Interest | H12: Principal | I12: End Balance
B13: 1 | C13: =CEILING(B13/12,1) -> 1 | D13: =IF(B13<=$C$7,"IO","Amort") -> IO | E13: =$C$5 -> 1680000 | F13: =IF(D13="IO",E13*$C$9,$C$10) -> 9100 | G13: =E13*$C$9 -> 9100 | H13: =F13-G13 -> 0 | I13: =E13-H13 -> 1680000
B14: =B13+1 -> 2 | C14: =CEILING(B14/12,1) -> 1 | D14: =IF(B14<=$C$7,"IO","Amort") -> IO | E14: =I13 -> 1680000 | F14: =IF(D14="IO",E14*$C$9,$C$10) -> 9100 | G14: =E14*$C$9 -> 9100 | H14: =F14-G14 -> 0 | I14: =E14-H14 -> 1680000
B15: =B14+1 -> 3 | C15: =CEILING(B15/12,1) -> 1 | D15: =IF(B15<=$C$7,"IO","Amort") -> IO | E15: =I14 -> 1680000 | F15: =IF(D15="IO",E15*$C$9,$C$10) -> 9100 | G15: =E15*$C$9 -> 9100 | H15: =F15-G15 -> 0 | I15: =E15-H15 -> 1680000
B16: =B15+1 -> 4 | C16: =CEILING(B16/12,1) -> 1 | D16: =IF(B16<=$C$7,"IO","Amort") -> IO | E16: =I15 -> 1680000 | F16: =IF(D16="IO",E16*$C$9,$C$10) -> 9100 | G16: =E16*$C$9 -> 9100 | H16: =F16-G16 -> 0 | I16: =E16-H16 -> 1680000
B17: =B16+1 -> 5 | C17: =CEILING(B17/12,1) -> 1 | D17: =IF(B17<=$C$7,"IO","Amort") -> IO | E17: =I16 -> 1680000 | F17: =IF(D17="IO",E17*$C$9,$C$10) -> 9100 | G17: =E17*$C$9 -> 9100 | H17: =F17-G17 -> 0 | I17: =E17-H17 -> 1680000
B18: =B17+1 -> 6 | C18: =CEILING(B18/12,1) -> 1 | D18: =IF(B18<=$C$7,"IO","Amort") -> IO | E18: =I17 -> 1680000 | F18: =IF(D18="IO",E18*$C$9,$C$10) -> 9100 | G18: =E18*$C$9 -> 9100 | H18: =F18-G18 -> 0 | I18: =E18-H18 -> 1680000
B19: =B18+1 -> 7 | C19: =CEILING(B19/12,1) -> 1 | D19: =IF(B19<=$C$7,"IO","Amort") -> IO | E19: =I18 -> 1680000 | F19: =IF(D19="IO",E19*$C$9,$C$10) -> 9100 | G19: =E19*$C$9 -> 9100 | H19: =F19-G19 -> 0 | I19: =E19-H19 -> 1680000
B20: =B19+1 -> 8 | C20: =CEILING(B20/12,1) -> 1 | D20: =IF(B20<=$C$7,"IO","Amort") -> IO | E20: =I19 -> 1680000 | F20: =IF(D20="IO",E20*$C$9,$C$10) -> 9100 | G20: =E20*$C$9 -> 9100 | H20: =F20-G20 -> 0 | I20: =E20-H20 -> 1680000
B21: =B20+1 -> 9 | C21: =CEILING(B21/12,1) -> 1 | D21: =IF(B21<=$C$7,"IO","Amort") -> IO | E21: =I20 -> 1680000 | F21: =IF(D21="IO",E21*$C$9,$C$10) -> 9100 | G21: =E21*$C$9 -> 9100 | H21: =F21-G21 -> 0 | I21: =E21-H21 -> 1680000
B22: =B21+1 -> 10 | C22: =CEILING(B22/12,1) -> 1 | D22: =IF(B22<=$C$7,"IO","Amort") -> IO | E22: =I21 -> 1680000 | F22: =IF(D22="IO",E22*$C$9,$C$10) -> 9100 | G22: =E22*$C$9 -> 9100 | H22: =F22-G22 -> 0 | I22: =E22-H22 -> 1680000
B23: =B22+1 -> 11 | C23: =CEILING(B23/12,1) -> 1 | D23: =IF(B23<=$C$7,"IO","Amort") -> IO | E23: =I22 -> 1680000 | F23: =IF(D23="IO",E23*$C$9,$C$10) -> 9100 | G23: =E23*$C$9 -> 9100 | H23: =F23-G23 -> 0 | I23: =E23-H23 -> 1680000
B24: =B23+1 -> 12 | C24: =CEILING(B24/12,1) -> 1 | D24: =IF(B24<=$C$7,"IO","Amort") -> IO | E24: =I23 -> 1680000 | F24: =IF(D24="IO",E24*$C$9,$C$10) -> 9100 | G24: =E24*$C$9 -> 9100 | H24: =F24-G24 -> 0 | I24: =E24-H24 -> 1680000
B25: =B24+1 -> 13 | C25: =CEILING(B25/12,1) -> 2 | D25: =IF(B25<=$C$7,"IO","Amort") -> IO | E25: =I24 -> 1680000 | F25: =IF(D25="IO",E25*$C$9,$C$10) -> 9100 | G25: =E25*$C$9 -> 9100 | H25: =F25-G25 -> 0 | I25: =E25-H25 -> 1680000
... B132: =B131+1 -> 120 | C132: =CEILING(B132/12,1) -> 10 | D132: =IF(B132<=$C$7,"IO","Amort") -> Amort | E132: =I131 -> 1491969.4 | F132: =IF(D132="IO",E132*$C$9,$C$10) -> 10618.743 | G132: =E132*$C$9 -> 8081.501 | H132: =F132-G132 -> 2537.2418 | I132: =E132-H132 -> 1489432.2

Sheet Inputs
A1: MULTIFAMILY ACQUISITION — INPUTS
A2: All inputs below drive the model. Blue = hardcoded input. Black = formula output.
A4: ACQUISITION & PROPERTY
A5: Property Name | B5: West 35th Street, Austin, Texas
A6: Acquisition Price ($) | B6: 2400000
A7: Closing Costs (%) | B7: 0.02
A8: Closing Costs ($) | B8: =B6*B7 -> 48000
A9: Total Acquisition Cost ($) | B9: =B6+B8 -> 2448000
A11: UNIT MIX & RENT SCHEDULE
A12: Unit Type | B12: Beds | C12: Baths | D12: # Units | E12: Avg SF | F12: Avg Rent / Mo ($) | G12: Mo Revenue ($) | H12: Ann Revenue ($)
A13: 0BR/1BA | B13: 0 | C13: 1 | D13: 7 | E13: 419.84 | F13: 1172.36 | G13: =D13*F13 -> 8206.52 | H13: =G13*12 -> 98478.24
A14: 1BR/1BA | B14: 1 | C14: 1 | D14: 7 | E14: 681.36 | F14: 1369.34 | G14: =D14*F14 -> 9585.38 | H14: =G14*12 -> 115024.56
A15: 2BR/2BA | B15: 2 | C15: 2 | D15: 6 | E15: 1090.74 | F15: 2266.7 | G15: =D15*F15 -> 13600.2 | H15: =G15*12 -> 163202.4
G16: =D16*F16 -> 0 | H16: =G16*12 -> 0
G17: =D17*F17 -> 0 | H17: =G17*12 -> 0
G18: =D18*F18 -> 0 | H18: =G18*12 -> 0
G19: =D19*F19 -> 0 | H19: =G19*12 -> 0
A20: TOTALS | D20: =SUM(D13:D19) -> 20 | E20: =SUMPRODUCT(D13:D19,E13:E19)/SUM(D13:D19) -> 712.642 | F20: =SUMPRODUCT(D13:D19,F13:F19)/SUM(D13:D19) -> 1569.605 | G20: =SUM(G13:G19) -> 31392.1 | H20: =SUM(H13:H19) -> 376705.2
A22: Total Units (auto) | B22: =D20 -> 20
A23: Gross Potential Rent / Yr ($) | B23: =H20 -> 376705.2
A25: RENOVATION
A26: Renovation Cost / Unit ($) | B26: 12500
A27: Total Renovation Budget ($) | B27: =B26*B22 -> 250000
A29: REVENUE ASSUMPTIONS
A30: Vacancy & Credit Loss (%) | B30: 0.07
A31: Other Income / Unit / Month ($) | B31: 75
A33: OPERATING EXPENSES
A34: Real Estate Taxes / Unit / Yr ($) | B34: 2400
A35: Insurance / Unit / Yr ($) | B35: 900
A36: Management Fee (% of EGI) | B36: 0.05
A37: Repairs & Maintenance / Unit / Yr ($) | B37: 1200
A38: CapEx Reserve / Unit / Yr ($) | B38: 300
A39: OpEx Growth Rate (%) | B39: 0.03
A41: DEBT ASSUMPTIONS
A42: Loan Type | B42: Agency/Perm
A43: LTV (%) | B43: 0.7
A44: Loan Amount ($) | B44: =B6*B43 -> 1680000
A45: Interest Rate (%) | B45: 0.065
A46: IO Period (Months) | B46: 24
A47: Amortization (Years) | B47: 30
...

Sheet ZZZOLD
