Workbook

Sheet Raw Comps
B1: RAW RENT COMPS — COMPARABLE LISTINGS
B2: API-ingested comp data. Do not edit manually — refreshed automatically on import.
B3: # | C3: Purchase Price | D3: Improvements | E3: rank | F3: distance_m | G3: distance_km | H3: filter_beds | I3: filter_baths | J3: type | K3: formattedAddress | L3: price | M3: bedrooms | N3: bathrooms | O3: squareFootage | P3: propertyType | Q3: listing_status | R3: daysOnMarket | S3: latitude | T3: longitude | U3: url | V3: id
B4: 1 | E4: 1 | F4: 5400 | G4: 5.4 | H4: 2 | I4: 2 | K4: 40 Harrison St, Unit 32HI, New York, NY 10013 | L4: 8095 | M4: 2 | N4: 2 | P4: Apartment | Q4: Active | R4: 1 | S4: 40.718975 | T4: -74.010757 | V4: 40-Harrison-St,-Unit-32HI,-New-York,-NY-10013
B5: 2 | E5: 2 | F5: 5432 | G5: 5.432 | H5: 2 | I5: 2 | K5: 80 N Moore St, Unit 36LM, New York, NY 10013 | L5: 8295 | M5: 2 | N5: 2 | P5: Apartment | Q5: Active | R5: 1 | S5: 40.719585 | T5: -74.010941 | V5: 80-N-Moore-St,-Unit-36LM,-New-York,-NY-10013
B6: 3 | E6: 3 | F6: 5502 | G6: 5.502 | H6: 2 | I6: 2 | K6: 201-205 W 11th St, Unit F, New York, NY 10014 | L6: 6600 | M6: 2 | N6: 2 | O6: 630 | P6: Apartment | Q6: Active | R6: 1 | S6: 40.73661 | T6: -74.001289 | V6: 201-205-W-11th-St,-Unit-F,-New-York,-NY-10014
B7: 4 | E7: 4 | F7: 7146 | G7: 7.146 | H7: 2 | I7: 2 | K7: 435 E 79th St, Unit 11, New York, NY 10075 | L7: 7100 | M7: 2 | N7: 2 | O7: 1145 | P7: Apartment | Q7: Active | R7: 1 | S7: 40.77174 | T7: -73.950729 | V7: 435-E-79th-St,-Unit-11,-New-York,-NY-10075
B8: 5 | E8: 5 | F8: 9049 | G8: 9.049 | H8: 2 | I8: 2 | K8: 120 W 86th St, Unit B, New York, NY 10024 | L8: 7600 | M8: 2 | N8: 2 | P8: Apartment | Q8: Active | R8: 1 | S8: 40.786713 | T8: -73.973106 | V8: 120-W-86th-St,-Unit-B,-New-York,-NY-10024

Sheet Rent Assumptions
B1: RENT ASSUMPTIONS — COMP-BASED UNIT MIX
B2: Search ID | C2: SRCH-20260225-002 | D2: Subject Lat | E2: 27.994007 | F2: Radius (mi) | G2: 5
B3: Email | C3: nikomoutop10@gmail.com | D3: Subject Long | E3: -82.467783 | F3: Max Comps | G3: 20
B4: Status | C4: Active | D4: Filter Combos | E4: 1 | F4: Selected Filter | G4: 1x1
B5: RENT ASSUMPTIONS — COMP-BASED UNIT MIX
B6: Auto-populated from Raw Comps tab. Aggregated by bed/bath type for use in Assumptions.
B7: Unit Type | C7: Beds | D7: Baths | E7: Count | F7: Model Inputs | G7: Avg SF | H7: Avg Rent / Mo ($)
B8: =IF(OR(E8=0,E8=""),"",C8&"BR/"&D8&"BA") | C8: {=_xlfn._xlws.SORT(_xlfn.UNIQUE(_xlfn._xlws.FILTER('Raw Comps'!$J$4:$K$998,'Raw Comps'!$J$4:$J$998<>"")),1,1)} -> #VALUE! | E8: =IF(D8=0,"",COUNTIFS('Raw Comps'!$J$3:$J$998,C8,'Raw Comps'!$K$3:$K$998,D8)) | G8: =IFERROR(AVERAGEIFS('Raw Comps'!$L$3:$L$998,'Raw Comps'!$J$3:$J$998,C8,'Raw Comps'!$K$3:$K$998,D8),"") | H8: =IFERROR(AVERAGEIFS('Raw Comps'!$I$3:$I$998,'Raw Comps'!$J$3:$J$998,C8,'Raw Comps'!$K$3:$K$998,D8),"")
B9: =IF(OR(E9=0,E9=""),"",C9&"BR/"&D9&"BA") | E9: =IF(D9=0,"",COUNTIFS('Raw Comps'!$J$3:$J$998,C9,'Raw Comps'!$K$3:$K$998,D9)) | G9: =IFERROR(AVERAGEIFS('Raw Comps'!$L$3:$L$998,'Raw Comps'!$J$3:$J$998,C9,'Raw Comps'!$K$3:$K$998,D9),"") | H9: =IFERROR(AVERAGEIFS('Raw Comps'!$I$3:$I$998,'Raw Comps'!$J$3:$J$998,C9,'Raw Comps'!$K$3:$K$998,D9),"")
B10: =IF(OR(E10=0,E10=""),"",C10&"BR/"&D10&"BA") | E10: =IF(D10=0,"",COUNTIFS('Raw Comps'!$J$3:$J$998,C10,'Raw Comps'!$K$3:$K$998,D10)) | G10: =IFERROR(AVERAGEIFS('Raw Comps'!$L$3:$L$998,'Raw Comps'!$J$3:$J$998,C10,'Raw Comps'!$K$3:$K$998,D10),"") | H10: =IFERROR(AVERAGEIFS('Raw Comps'!$I$3:$I$998,'Raw Comps'!$J$3:$J$998,C10,'Raw Comps'!$K$3:$K$998,D10),"")
B11: =IF(OR(E11=0,E11=""),"",C11&"BR/"&D11&"BA") | E11: =IF(D11=0,"",COUNTIFS('Raw Comps'!$J$3:$J$998,C11,'Raw Comps'!$K$3:$K$998,D11)) | G11: =IFERROR(AVERAGEIFS('Raw Comps'!$L$3:$L$998,'Raw Comps'!$J$3:$J$998,C11,'Raw Comps'!$K$3:$K$998,D11),"") | H11: =IFERROR(AVERAGEIFS('Raw Comps'!$I$3:$I$998,'Raw Comps'!$J$3:$J$998,C11,'Raw Comps'!$K$3:$K$998,D11),"")
B12: =IF(OR(E12=0,E12=""),"",C12&"BR/"&D12&"BA") | E12: =IF(D12=0,"",COUNTIFS('Raw Comps'!$J$3:$J$998,C12,'Raw Comps'!$K$3:$K$998,D12)) | G12: =IFERROR(AVERAGEIFS('Raw Comps'!$L$3:$L$998,'Raw Comps'!$J$3:$J$998,C12,'Raw Comps'!$K$3:$K$998,D12),"") | H12: =IFERROR(AVERAGEIFS('Raw Comps'!$I$3:$I$998,'Raw Comps'!$J$3:$J$998,C12,'Raw Comps'!$K$3:$K$998,D12),"")
B13: =IF(OR(E13=0,E13=""),"",C13&"BR/"&D13&"BA") | E13: =IF(D13=0,"",COUNTIFS('Raw Comps'!$J$3:$J$998,C13,'Raw Comps'!$K$3:$K$998,D13)) | G13: =IFERROR(AVERAGEIFS('Raw Comps'!$L$3:$L$998,'Raw Comps'!$J$3:$J$998,C13,'Raw Comps'!$K$3:$K$998,D13),"") | H13: =IFERROR(AVERAGEIFS('Raw Comps'!$I$3:$I$998,'Raw Comps'!$J$3:$J$998,C13,'Raw Comps'!$K$3:$K$998,D13),"")
B14: =IF(OR(E14=0,E14=""),"",C14&"BR/"&D14&"BA") | E14: =IF(D14=0,"",COUNTIFS('Raw Comps'!$J$3:$J$998,C14,'Raw Comps'!$K$3:$K$998,D14)) | G14: =IFERROR(AVERAGEIFS('Raw Comps'!$L$3:$L$998,'Raw Comps'!$J$3:$J$998,C14,'Raw Comps'!$K$3:$K$998,D14),"") | H14: =IFERROR(AVERAGEIFS('Raw Comps'!$I$3:$I$998,'Raw Comps'!$J$3:$J$998,C14,'Raw Comps'!$K$3:$K$998,D14),"")
B15: =IF(OR(E15=0,E15=""),"",C15&"BR/"&D15&"BA") | E15: =IF(D15=0,"",COUNTIFS('Raw Comps'!$J$3:$J$998,C15,'Raw Comps'!$K$3:$K$998,D15)) | G15: =IFERROR(AVERAGEIFS('Raw Comps'!$L$3:$L$998,'Raw Comps'!$J$3:$J$998,C15,'Raw Comps'!$K$3:$K$998,D15),"") | H15: =IFERROR(AVERAGEIFS('Raw Comps'!$I$3:$I$998,'Raw Comps'!$J$3:$J$998,C15,'Raw Comps'!$K$3:$K$998,D15),"")
B16: =IF(OR(E16=0,E16=""),"",C16&"BR/"&D16&"BA") | E16: =IF(D16=0,"",COUNTIFS('Raw Comps'!$J$3:$J$998,C16,'Raw Comps'!$K$3:$K$998,D16)) | G16: =IFERROR(AVERAGEIFS('Raw Comps'!$L$3:$L$998,'Raw Comps'!$J$3:$J$998,C16,'Raw Comps'!$K$3:$K$998,D16),"") | H16: =IFERROR(AVERAGEIFS('Raw Comps'!$I$3:$I$998,'Raw Comps'!$J$3:$J$998,C16,'Raw Comps'!$K$3:$K$998,D16),"")
B17: =IF(OR(E17=0,E17=""),"",C17&"BR/"&D17&"BA") | E17: =IF(D17=0,"",COUNTIFS('Raw Comps'!$J$3:$J$998,C17,'Raw Comps'!$K$3:$K$998,D17)) | G17: =IFERROR(AVERAGEIFS('Raw Comps'!$L$3:$L$998,'Raw Comps'!$J$3:$J$998,C17,'Raw Comps'!$K$3:$K$998,D17),"") | H17: =IFERROR(AVERAGEIFS('Raw Comps'!$I$3:$I$998,'Raw Comps'!$J$3:$J$998,C17,'Raw Comps'!$K$3:$K$998,D17),"")
B18: =IF(OR(E18=0,E18=""),"",C18&"BR/"&D18&"BA") | E18: =IF(D18=0,"",COUNTIFS('Raw Comps'!$J$3:$J$998,C18,'Raw Comps'!$K$3:$K$998,D18)) | G18: =IFERROR(AVERAGEIFS('Raw Comps'!$L$3:$L$998,'Raw Comps'!$J$3:$J$998,C18,'Raw Comps'!$K$3:$K$998,D18),"") | H18: =IFERROR(AVERAGEIFS('Raw Comps'!$I$3:$I$998,'Raw Comps'!$J$3:$J$998,C18,'Raw Comps'!$K$3:$K$998,D18),"")
B19: =IF(OR(E19=0,E19=""),"",C19&"BR/"&D19&"BA") | E19: =IF(D19=0,"",COUNTIFS('Raw Comps'!$J$3:$J$998,C19,'Raw Comps'!$K$3:$K$998,D19)) | G19: =IFERROR(AVERAGEIFS('Raw Comps'!$L$3:$L$998,'Raw Comps'!$J$3:$J$998,C19,'Raw Comps'!$K$3:$K$998,D19),"") | H19: =IFERROR(AVERAGEIFS('Raw Comps'!$I$3:$I$998,'Raw Comps'!$J$3:$J$998,C19,'Raw Comps'!$K$3:$K$998,D19),"")
B20: =IF(OR(E20=0,E20=""),"",C20&"BR/"&D20&"BA") | E20: =IF(D20=0,"",COUNTIFS('Raw Comps'!$J$3:$J$998,C20,'Raw Comps'!$K$3:$K$998,D20)) | G20: =IFERROR(AVERAGEIFS('Raw Comps'!$L$3:$L$998,'Raw Comps'!$J$3:$J$998,C20,'Raw Comps'!$K$3:$K$998,D20),"") | H20: =IFERROR(AVERAGEIFS('Raw Comps'!$I$3:$I$998,'Raw Comps'!$J$3:$J$998,C20,'Raw Comps'!$K$3:$K$998,D20),"")
... B30: =IF(OR(E30=0,E30=""),"",C30&"BR/"&D30&"BA") | E30: =IF(D30=0,"",COUNTIFS('Raw Comps'!$J$3:$J$998,C30,'Raw Comps'!$K$3:$K$998,D30)) | G30: =IFERROR(AVERAGEIFS('Raw Comps'!$L$3:$L$998,'Raw Comps'!$J$3:$J$998,C30,'Raw Comps'!$K$3:$K$998,D30),"") | H30: =IFERROR(AVERAGEIFS('Raw Comps'!$I$3:$I$998,'Raw Comps'!$J$3:$J$998,C30,'Raw Comps'!$K$3:$K$998,D30),"")

Sheet Assumptions
B2: MULTIFAMILY ACQUISITION — ASSUMPTIONS
B3: All inputs below drive the model. Blue = hardcoded input. Black = formula output.
B5: ACQUISITION & PROPERTY
B6: Property Name | C6: Sample Multifamily | D6: Total Units | E6: 20
B7: Acquisition Price ($) | C7: 12500000
B8: Closing Costs (%) | C8: 0.02
B9: Closing Costs ($) | C9: =C7*C8 -> 250000
B10: Total Acquisition Cost ($) | C10: =C7+C9 -> 12750000
B12: UNIT MIX & RENT SCHEDULE
B13: Unit Types | C13: Monthly Rent/Unit | D13: Count | E13: Avg SF | F13: Rent / SF | G13: Total SF | H13: Total Monthly Rent | I13: Total Annual Rent
B14: 1BR/2BA | C14: =IFERROR(AVERAGEIF('Rent Assumptions'!$B$8:$B$30,$B14,'Rent Assumptions'!$H$8:$H$30),"") | D14: =IF(B14<>"", E$6/COUNTA(B$14:B$20), "") -> 6.6666667 | E14: =IFERROR(AVERAGEIF('Rent Assumptions'!$B$8:$B$30,$B14,'Rent Assumptions'!$G$8:$G$30),"") | F14: =IFERROR(C14/E14,"") | G14: =IFERROR(E14*D14,"") | H14: =IFERROR(C14*D14,"") | I14: =IFERROR(H14*12,"")
B15: 1BR/2BA | C15: =IFERROR(AVERAGEIF('Rent Assumptions'!$B$8:$B$30,$B15,'Rent Assumptions'!$H$8:$H$30),"") | D15: =IF(B15<>"", E$6/COUNTA(B$14:B$20), "") -> 6.6666667 | E15: =IFERROR(AVERAGEIF('Rent Assumptions'!$B$8:$B$30,$B15,'Rent Assumptions'!$G$8:$G$30),"") | F15: =IFERROR(C15/E15,"") | G15: =IFERROR(E15*D15,"") | H15: =IFERROR(C15*D15,"") | I15: =IFERROR(H15*12,"")
B16: 1BR/1BA | C16: =IFERROR(AVERAGEIF('Rent Assumptions'!$B$8:$B$30,$B16,'Rent Assumptions'!$H$8:$H$30),"") | D16: =IF(B16<>"", E$6/COUNTA(B$14:B$20), "") -> 6.6666667 | E16: =IFERROR(AVERAGEIF('Rent Assumptions'!$B$8:$B$30,$B16,'Rent Assumptions'!$G$8:$G$30),"") | F16: =IFERROR(C16/E16,"") | G16: =IFERROR(E16*D16,"") | H16: =IFERROR(C16*D16,"") | I16: =IFERROR(H16*12,"")
C17: =IFERROR(AVERAGEIF('Rent Assumptions'!$B$8:$B$30,$B17,'Rent Assumptions'!$H$8:$H$30),"") | D17: =IF(B17<>"", E$6/COUNTA(B$14:B$20), "") | E17: =IFERROR(AVERAGEIF('Rent Assumptions'!$B$8:$B$30,$B17,'Rent Assumptions'!$G$8:$G$30),"") | F17: =IFERROR(C17/E17,"") | G17: =IFERROR(E17*D17,"") | H17: =IFERROR(C17*D17,"") | I17: =IFERROR(H17*12,"")
C18: =IFERROR(AVERAGEIF('Rent Assumptions'!$B$8:$B$30,$B18,'Rent Assumptions'!$H$8:$H$30),"") | D18: =IF(B18<>"", E$6/COUNTA(B$14:B$20), "") | E18: =IFERROR(AVERAGEIF('Rent Assumptions'!$B$8:$B$30,$B18,'Rent Assumptions'!$G$8:$G$30),"") | F18: =IFERROR(C18/E18,"") | G18: =IFERROR(E18*D18,"") | H18: =IFERROR(C18*D18,"") | I18: =IFERROR(H18*12,"")
C19: =IFERROR(AVERAGEIF('Rent Assumptions'!$B$8:$B$30,$B19,'Rent Assumptions'!$H$8:$H$30),"") | D19: =IF(B19<>"", E$6/COUNTA(B$14:B$20), "") | E19: =IFERROR(AVERAGEIF('Rent Assumptions'!$B$8:$B$30,$B19,'Rent Assumptions'!$G$8:$G$30),"") | F19: =IFERROR(C19/E19,"") | G19: =IFERROR(E19*D19,"") | H19: =IFERROR(C19*D19,"") | I19: =IFERROR(H19*12,"")
C20: =IFERROR(AVERAGEIF('Rent Assumptions'!$B$8:$B$30,$B20,'Rent Assumptions'!$H$8:$H$30),"") | D20: =IF(B20<>"", E$6/COUNTA(B$14:B$20), "") | E20: =IFERROR(AVERAGEIF('Rent Assumptions'!$B$8:$B$30,$B20,'Rent Assumptions'!$G$8:$G$30),"") | F20: =IFERROR(C20/E20,"") | G20: =IFERROR(E20*D20,"") | H20: =IFERROR(C20*D20,"") | I20: =IFERROR(H20*12,"")
D21: =SUM(D14:D20) -> 20 | E21: =IFERROR(SUMPRODUCT(E14:E20,D14:D20)/SUM(D14:D20),"") -> 0 | F21: =IFERROR(H21/(E21*D21),"") | G21: =SUM(G14:G20) -> 0 | H21: =SUM(H14:H20) -> 0 | I21: =SUM(I14:I20) -> 0
B23: Total Units (auto) | C23: =D21 -> 20
B24: Gross Potential Rent / Yr ($) | C24: =I21 -> 0
B26: CAPITAL COSTS
B27: Total Capital Cost Budget ($) | C27: 1000000 | D27: =IF(C27=0,"Enter total above",IF(E35=C27,"✓ Balanced","⚠ Unallocated: "&TEXT(C27-E35,"$#,##0"))) -> ⚠ Unallocated: $1,000,000
B29: Unit Type | C29: Total SF | D29: SF % of Total | E29: Allocated Cost ($) | F29: Cost / SF ($) | G29: Cost / Unit ($)
B30: =IF(B14<>""," "&B14,"") -> 1BR/2BA | C30: =IFERROR(G14,"") | D30: =IFERROR(C30/C$35,"") | E30: =IFERROR(C$27*D30,"") | F30: =IFERROR(E30/C30,"") | G30: =IFERROR(E30/D14,"")
B31: =IF(B15<>""," "&B15,"") -> 1BR/2BA | C31: =IFERROR(G15,"") | D31: =IFERROR(C31/C$35,"") | E31: =IFERROR(C$27*D31,"") | F31: =IFERROR(E31/C31,"") | G31: =IFERROR(E31/D15,"")
B32: =IF(B16<>""," "&B16,"") -> 1BR/1BA | C32: =IFERROR(G16,"") | D32: =IFERROR(C32/C$35,"") | E32: =IFERROR(C$27*D32,"") | F32: =IFERROR(E32/C32,"") | G32: =IFERROR(E32/D16,"")
B33: =IF(B17<>""," "&B17,"") | C33: =IFERROR(G17,"") | D33: =IFERROR(C33/C$35,"") | E33: =IFERROR(C$27*D33,"") | F33: =IFERROR(E33/C33,"") | G33: =IFERROR(E33/D17,"")
B34: =IF(B18<>""," "&B18,"") | C34: =IFERROR(G18,"") | D34: =IFERROR(C34/C$35,"") | E34: =IFERROR(C$27*D34,"") | F34: =IFERROR(E34/C34,"") | G34: =IFERROR(E34/D18,"")
B35: Total | C35: =SUM(C30:C34) -> 0 | D35: =SUM(D30:D32) -> 0 | E35: =SUM(E30:E32) -> 0 | F35: =IFERROR(C27/C35,"") | G35: =IFERROR(C27/C23,"") -> 50000
B38: REVENUE ASSUMPTIONS
B39: Vacancy & Credit Loss (%) | C39: 0.07
B40: Other Income / Unit / Month ($) | C40: 75
B42: OPERATING EXPENSES
B43: OpEx Ratio (% of EGI) | C43: 0.35
B44: OpEx Growth Rate (%) | C44: 0.03
B50: DEBT ASSUMPTIONS
B51: Loan Type | C51: Agency/Perm
B52: LTV (%) | C52: 0.7
B53: Loan Amount ($) | C53: =C7*C52 -> 8750000
B54: Interest Rate (%) | C54: 0.065
...

Sheet Pricing Scenarios
B1: PRICING SCENARIOS — CAP RATE-BASED ACQUISITION ANALYSIS
B2: Implied acquisition price = Year 1 NOI ÷ Entry Cap Rate. Returns linked live to model. Edit thresholds to flag scenarios.
B4: RETURN THRESHOLDS (edit these) | E4: Year 1 NOI (live): | F4: ='Cash Flow'!E21 -> 11207.43
B5: Min IRR Target (Levered) | C5: 0.1 | E5: Hold Period (live): | F5: =Assumptions!C62 -> 5
B6: Min Avg CoC Target | C6: 0.06 | E6: Exit Cap (live): | F6: =Assumptions!C63 -> 0.06
B8: SCENARIO TABLE — Entry Cap Rate × Implied Price × Returns
B9: Entry Cap Rate | C9: Implied Acq Price | D9: LTV (live) | E9: Loan Amount | F9: Total Equity | G9: GP Equity | H9: LP Equity | I9: Year 1 NOI | J9: Year 1 CoC | K9: Avg CoC (hold) | L9: Levered IRR | M9: Exit Multiple | N9: CF0 | O9: CF1 | P9: CF2 | Q9: CF3 | R9: CF4 | S9: CF5
A10: =IF(ABS(C10-Assumptions!$C$7)<C10*0.02,"★ BASE",IF(Assumptions!$C$7>C10,"▼ OVERPRICE","▲ UPSIDE")) -> ▼ OVERPRICE | B10: 0.05 | C10: ='Cash Flow'!$E$21/B10 -> 224148.6 | D10: =Assumptions!$C$52 -> 0.7 | E10: =C10*D10 -> 156904.02 | F10: =C10*(1+Assumptions!$C$8)+Assumptions!$C$36-E10 -> 71727.552 | G10: =F10*Assumptions!$C$67 -> 7172.7552 | H10: =F10-G10 -> 64554.797 | I10: ='Cash Flow'!$E$21 -> 11207.43 | J10: =('Cash Flow'!$E$21-E10*Assumptions!$C$54)/F10 -> 0.0140625 | K10: =IFERROR(AVERAGE('Cash Flow'!$E$21-E10*Assumptions!$C$54,'Cash Flow'!$F$21-E10*Assumptions!$C$54,'Cash Flow'!$G$21+PMT(Assumptions!$C$54/12,Assumptions!$C$56*12,E10)*12,'Cash Flow'!$H$21+PMT(Assumptions!$C$54/12,Assumptions!$C$56*12,E10)*12,'Cash Flow'!$I$21+PMT(Assumptions!$C$54/12,Assumptions!$C$56*12,E10)*12)/F10,"-") -> 0.007944169 | L10: =IFERROR(IRR(N10:S10),"n/a") -> -0.060314325 | M10: =IFERROR((SUM(O10:S10)+N10)/(-N10)+1,"n/a") -> 0.73894254 | N10: =-F10 -> -71727.552 | O10: ='Cash Flow'!$E$21-E10*Assumptions!$C$54 -> 1008.6687 | P10: ='Cash Flow'!$F$21-E10*Assumptions!$C$54 -> 1344.8916 | Q10: ='Cash Flow'!$G$21+PMT(Assumptions!$C$54/12,Assumptions!$C$56*12,E10)*12 -> -99.716499 | R10: ='Cash Flow'!$H$21+PMT(Assumptions!$C$54/12,Assumptions!$C$56*12,E10)*12 -> 163.30119 | S10: ='Cash Flow'!$I$21+PMT(Assumptions!$C$54/12,Assumptions!$C$56*12,E10)*12+('Cash Flow'!$I$21/Assumptions!$C$63)*(1-Assumptions!$C$64)-(E10+CUMPRINC(Assumptions!$C$54/12,Assumptions!$C$56*12,E10,1,MIN(Assumptions!$C$62*12-Assumptions!$C$55,Assumptions!$C$56*12),0)) -> 50585.394
A11: =IF(ABS(C11-Assumptions!$C$7)<C11*0.02,"★ BASE",IF(Assumptions!$C$7>C11,"▼ OVERPRICE","▲ UPSIDE")) -> ▼ OVERPRICE | B11: 0.06 | C11: ='Cash Flow'!$E$21/B11 -> 186790.5 | D11: =Assumptions!$C$52 -> 0.7 | E11: =C11*D11 -> 130753.35 | F11: =C11*(1+Assumptions!$C$8)+Assumptions!$C$36-E11 -> 59772.96 | G11: =F11*Assumptions!$C$67 -> 5977.296 | H11: =F11-G11 -> 53795.664 | I11: ='Cash Flow'!$E$21 -> 11207.43 | J11: =('Cash Flow'!$E$21-E11*Assumptions!$C$54)/F11 -> 0.0453125 | K11: =IFERROR(AVERAGE('Cash Flow'!$E$21-E11*Assumptions!$C$54,'Cash Flow'!$F$21-E11*Assumptions!$C$54,'Cash Flow'!$G$21+PMT(Assumptions!$C$54/12,Assumptions!$C$56*12,E11)*12,'Cash Flow'!$H$21+PMT(Assumptions!$C$54/12,Assumptions!$C$56*12,E11)*12,'Cash Flow'!$I$21+PMT(Assumptions!$C$54/12,Assumptions!$C$56*12,E11)*12)/F11,"-") -> 0.040818146 | L11: =IFERROR(IRR(N11:S11),"n/a") -> 0.085245031 | M11: =IFERROR((SUM(O11:S11)+N11)/(-N11)+1,"n/a") -> 1.4649822 | N11: =-F11 -> -59772.96 | O11: ='Cash Flow'!$E$21-E11*Assumptions!$C$54 -> 2708.4623 | P11: ='Cash Flow'!$F$21-E11*Assumptions!$C$54 -> 3044.6852 | Q11: ='Cash Flow'!$G$21+PMT(Assumptions!$C$54/12,Assumptions!$C$56*12,E11)*12 -> 1883.7638 | R11: ='Cash Flow'!$H$21+PMT(Assumptions!$C$54/12,Assumptions!$C$56*12,E11)*12 -> 2146.7815 | S11: ='Cash Flow'!$I$21+PMT(Assumptions!$C$54/12,Assumptions!$C$56*12,E11)*12+('Cash Flow'!$I$21/Assumptions!$C$63)*(1-Assumptions!$C$64)-(E11+CUMPRINC(Assumptions!$C$54/12,Assumptions!$C$56*12,E11,1,MIN(Assumptions!$C$62*12-Assumptions!$C$55,Assumptions!$C$56*12),0)) -> 77782.629
A12: =IF(ABS(C12-Assumptions!$C$7)<C12*0.02,"★ BASE",IF(Assumptions!$C$7>C12,"▼ OVERPRICE","▲ UPSIDE")) -> ▼ OVERPRICE | B12: 0.07 | C12: ='Cash Flow'!$E$21/B12 -> 160106.14 | D12: =Assumptions!$C$52 -> 0.7 | E12: =C12*D12 -> 112074.3 | F12: =C12*(1+Assumptions!$C$8)+Assumptions!$C$36-E12 -> 51233.966 | G12: =F12*Assumptions!$C$67 -> 5123.3966 | H12: =F12-G12 -> 46110.569 | I12: ='Cash Flow'!$E$21 -> 11207.43 | J12: =('Cash Flow'!$E$21-E12*Assumptions!$C$54)/F12 -> 0.0765625 | K12: =IFERROR(AVERAGE('Cash Flow'!$E$21-E12*Assumptions!$C$54,'Cash Flow'!$F$21-E12*Assumptions!$C$54,'Cash Flow'!$G$21+PMT(Assumptions!$C$54/12,Assumptions!$C$56*12,E12)*12,'Cash Flow'!$H$21+PMT(Assumptions!$C$54/12,Assumptions!$C$56*12,E12)*12,'Cash Flow'!$I$21+PMT(Assumptions!$C$54/12,Assumptions!$C$56*12,E12)*12)/F12,"-") -> 0.073692122 | L12: =IFERROR(IRR(N12:S12),"n/a") -> 0.18759618 | M12: =IFERROR((SUM(O12:S12)+N12)/(-N12)+1,"n/a") -> 2.1910218 | N12: =-F12 -> -51233.966 | O12: ='Cash Flow'!$E$21-E12*Assumptions!$C$54 -> 3922.6005 | P12: ='Cash Flow'!$F$21-E12*Assumptions!$C$54 -> 4258.8234 | Q12: ='Cash Flow'!$G$21+PMT(Assumptions!$C$54/12,Assumptions!$C$56*12,E12)*12 -> 3300.5354 | R12: ='Cash Flow'!$H$21+PMT(Assumptions!$C$54/12,Assumptions!$C$56*12,E12)*12 -> 3563.5531 | S12: ='Cash Flow'!$I$21+PMT(Assumptions!$C$54/12,Assumptions!$C$56*12,E12)*12+('Cash Flow'!$I$21/Assumptions!$C$63)*(1-Assumptions!$C$64)-(E12+CUMPRINC(Assumptions!$C$54/12,Assumptions!$C$56*12,E12,1,MIN(Assumptions!$C$62*12-Assumptions!$C$55,Assumptions!$C$56*12),0)) -> 97209.226
A13: =IF(ABS(C13-Assumptions!$C$7)<C13*0.02,"★ BASE",IF(Assumptions!$C$7>C13,"▼ OVERPRICE","▲ UPSIDE")) -> ▼ OVERPRICE | B13: 0.08 | C13: ='Cash Flow'!$E$21/B13 -> 140092.88 | D13: =Assumptions!$C$52 -> 0.7 | E13: =C13*D13 -> 98065.012 | F13: =C13*(1+Assumptions!$C$8)+Assumptions!$C$36-E13 -> 44829.72 | G13: =F13*Assumptions!$C$67 -> 4482.972 | H13: =F13-G13 -> 40346.748 | I13: ='Cash Flow'!$E$21 -> 11207.43 | J13: =('Cash Flow'!$E$21-E13*Assumptions!$C$54)/F13 -> 0.1078125 | K13: =IFERROR(AVERAGE('Cash Flow'!$E$21-E13*Assumptions!$C$54,'Cash Flow'!$F$21-E13*Assumptions!$C$54,'Cash Flow'!$G$21+PMT(Assumptions!$C$54/12,Assumptions!$C$56*12,E13)*12,'Cash Flow'!$H$21+PMT(Assumptions!$C$54/12,Assumptions!$C$56*12,E13)*12,'Cash Flow'!$I$21+PMT(Assumptions!$C$54/12,Assumptions!$C$56*12,E13)*12)/F13,"-") -> 0.1065661 | L13: =IFERROR(IRR(N13:S13),"n/a") -> 0.26949006 | M13: =IFERROR((SUM(O13:S13)+N13)/(-N13)+1,"n/a") -> 2.9170615 | N13: =-F13 -> -44829.72 | O13: ='Cash Flow'!$E$21-E13*Assumptions!$C$54 -> 4833.2042 | P13: ='Cash Flow'!$F$21-E13*Assumptions!$C$54 -> 5169.4271 | Q13: ='Cash Flow'!$G$21+PMT(Assumptions!$C$54/12,Assumptions!$C$56*12,E13)*12 -> 4363.1141 | R13: ='Cash Flow'!$H$21+PMT(Assumptions!$C$54/12,Assumptions!$C$56*12,E13)*12 -> 4626.1318 | S13: ='Cash Flow'!$I$21+PMT(Assumptions!$C$54/12,Assumptions!$C$56*12,E13)*12+('Cash Flow'!$I$21/Assumptions!$C$63)*(1-Assumptions!$C$64)-(E13+CUMPRINC(Assumptions!$C$54/12,Assumptions!$C$56*12,E13,1,MIN(Assumptions!$C$62*12-Assumptions!$C$55,Assumptions!$C$56*12),0)) -> 111779.17
A14: =IF(ABS(C14-Assumptions!$C$7)<C14*0.02,"★ BASE",IF(Assumptions!$C$7>C14,"▼ OVERPRICE","▲ UPSIDE")) -> ▼ OVERPRICE | B14: 0.09 | C14: ='Cash Flow'!$E$21/B14 -> 124527 | D14: =Assumptions!$C$52 -> 0.7 | E14: =C14*D14 -> 87168.9 | F14: =C14*(1+Assumptions!$C$8)+Assumptions!$C$36-E14 -> 39848.64 | G14: =F14*Assumptions!$C$67 -> 3984.864 | H14: =F14-G14 -> 35863.776 | I14: ='Cash Flow'!$E$21 -> 11207.43 | J14: =('Cash Flow'!$E$21-E14*Assumptions!$C$54)/F14 -> 0.1390625 | K14: =IFERROR(AVERAGE('Cash Flow'!$E$21-E14*Assumptions!$C$54,'Cash Flow'!$F$21-E14*Assumptions!$C$54,'Cash Flow'!$G$21+PMT(Assumptions!$C$54/12,Assumptions!$C$56*12,E14)*12,'Cash Flow'!$H$21+PMT(Assumptions!$C$54/12,Assumptions!$C$56*12,E14)*12,'Cash Flow'!$I$21+PMT(Assumptions!$C$54/12,Assumptions!$C$56*12,E14)*12)/F14,"-") -> 0.13944008 | L14: =IFERROR(IRR(N14:S14),"n/a") -> 0.33922408 | M14: =IFERROR((SUM(O14:S14)+N14)/(-N14)+1,"n/a") -> 3.6431012 | N14: =-F14 -> -39848.64 | O14: ='Cash Flow'!$E$21-E14*Assumptions!$C$54 -> 5541.4515 | P14: ='Cash Flow'!$F$21-E14*Assumptions!$C$54 -> 5877.6744 | Q14: ='Cash Flow'!$G$21+PMT(Assumptions!$C$54/12,Assumptions!$C$56*12,E14)*12 -> 5189.5642 | R14: ='Cash Flow'!$H$21+PMT(Assumptions!$C$54/12,Assumptions!$C$56*12,E14)*12 -> 5452.5819 | S14: ='Cash Flow'!$I$21+PMT(Assumptions!$C$54/12,Assumptions!$C$56*12,E14)*12+('Cash Flow'!$I$21/Assumptions!$C$63)*(1-Assumptions!$C$64)-(E14+CUMPRINC(Assumptions!$C$54/12,Assumptions!$C$56*12,E14,1,MIN(Assumptions!$C$62*12-Assumptions!$C$55,Assumptions!$C$56*12),0)) -> 123111.35
A15: =IF(ABS(C15-Assumptions!$C$7)<C15*0.02,"★ BASE",IF(Assumptions!$C$7>C15,"▼ OVERPRICE","▲ UPSIDE")) -> ▼ OVERPRICE | B15: 0.1 | C15: ='Cash Flow'!$E$21/B15 -> 112074.3 | D15: =Assumptions!$C$52 -> 0.7 | E15: =C15*D15 -> 78452.01 | F15: =C15*(1+Assumptions!$C$8)+Assumptions!$C$36-E15 -> 35863.776 | G15: =F15*Assumptions!$C$67 -> 3586.3776 | H15: =F15-G15 -> 32277.398 | I15: ='Cash Flow'!$E$21 -> 11207.43 | J15: =('Cash Flow'!$E$21-E15*Assumptions!$C$54)/F15 -> 0.1703125 | K15: =IFERROR(AVERAGE('Cash Flow'!$E$21-E15*Assumptions!$C$54,'Cash Flow'!$F$21-E15*Assumptions!$C$54,'Cash Flow'!$G$21+PMT(Assumptions!$C$54/12,Assumptions!$C$56*12,E15)*12,'Cash Flow'!$H$21+PMT(Assumptions!$C$54/12,Assumptions!$C$56*12,E15)*12,'Cash Flow'!$I$21+PMT(Assumptions!$C$54/12,Assumptions!$C$56*12,E15)*12)/F15,"-") -> 0.17231405 | L15: =IFERROR(IRR(N15:S15),"n/a") -> 0.40083165 | M15: =IFERROR((SUM(O15:S15)+N15)/(-N15)+1,"n/a") -> 4.3691408 | N15: =-F15 -> -35863.776 | O15: ='Cash Flow'!$E$21-E15*Assumptions!$C$54 -> 6108.0494 | P15: ='Cash Flow'!$F$21-E15*Assumptions!$C$54 -> 6444.2723 | Q15: ='Cash Flow'!$G$21+PMT(Assumptions!$C$54/12,Assumptions!$C$56*12,E15)*12 -> 5850.7243 | R15: ='Cash Flow'!$H$21+PMT(Assumptions!$C$54/12,Assumptions!$C$56*12,E15)*12 -> 6113.742 | S15: ='Cash Flow'!$I$21+PMT(Assumptions!$C$54/12,Assumptions!$C$56*12,E15)*12+('Cash Flow'!$I$21/Assumptions!$C$63)*(1-Assumptions!$C$64)-(E15+CUMPRINC(Assumptions!$C$54/12,Assumptions!$C$56*12,E15,1,MIN(Assumptions!$C$62*12-Assumptions!$C$55,Assumptions!$C$56*12),0)) -> 132177.1
A16: =IF(ABS(C16-Assumptions!$C$7)<C16*0.02,"★ BASE",IF(Assumptions!$C$7>C16,"▼ OVERPRICE","▲ UPSIDE")) -> ▼ OVERPRICE | B16: 0.11 | C16: ='Cash Flow'!$E$21/B16 -> 101885.73 | D16: =Assumptions!$C$52 -> 0.7 | E16: =C16*D16 -> 71320.009 | F16: =C16*(1+Assumptions!$C$8)+Assumptions!$C$36-E16 -> 32603.433 | G16: =F16*Assumptions!$C$67 -> 3260.3433 | H16: =F16-G16 -> 29343.089 | I16: ='Cash Flow'!$E$21 -> 11207.43 | J16: =('Cash Flow'!$E$21-E16*Assumptions!$C$54)/F16 -> 0.2015625 | K16: =IFERROR(AVERAGE('Cash Flow'!$E$21-E16*Assumptions!$C$54,'Cash Flow'!$F$21-E16*Assumptions!$C$54,'Cash Flow'!$G$21+PMT(Assumptions!$C$54/12,Assumptions!$C$56*12,E16)*12,'Cash Flow'!$H$21+PMT(Assumptions!$C$54/12,Assumptions!$C$56*12,E16)*12,'Cash Flow'!$I$21+PMT(Assumptions!$C$54/12,Assumptions!$C$56*12,E16)*12)/F16,"-") -> 0.20518803 | L16: =IFERROR(IRR(N16:S16),"n/a") -> 0.45660127 | M16: =IFERROR((SUM(O16:S16)+N16)/(-N16)+1,"n/a") -> 5.0951805 | N16: =-F16 -> -32603.433 | O16: ='Cash Flow'!$E$21-E16*Assumptions!$C$54 -> 6571.6294 | P16: ='Cash Flow'!$F$21-E16*Assumptions!$C$54 -> 6907.8523 | Q16: ='Cash Flow'!$G$21+PMT(Assumptions!$C$54/12,Assumptions!$C$56*12,E16)*12 -> 6391.6735 | R16: ='Cash Flow'!$H$21+PMT(Assumptions!$C$54/12,Assumptions!$C$56*12,E16)*12 -> 6654.6912 | S16: ='Cash Flow'!$I$21+PMT(Assumptions!$C$54/12,Assumptions!$C$56*12,E16)*12+('Cash Flow'!$I$21/Assumptions!$C$63)*(1-Assumptions!$C$64)-(E16+CUMPRINC(Assumptions!$C$54/12,Assumptions!$C$56*12,E16,1,MIN(Assumptions!$C$62*12-Assumptions!$C$55,Assumptions!$C$56*12),0)) -> 139594.53
A17: =IF(ABS(C17-Assumptions!$C$7)<C17*0.02,"★ BASE",IF(Assumptions!$C$7>C17,"▼ OVERPRICE","▲ UPSIDE")) -> ▼ OVERPRICE | B17: 0.12 | C17: ='Cash Flow'!$E$21/B17 -> 93395.25 | D17: =Assumptions!$C$52 -> 0.7 | E17: =C17*D17 -> 65376.675 | F17: =C17*(1+Assumptions!$C$8)+Assumptions!$C$36-E17 -> 29886.48 | G17: =F17*Assumptions!$C$67 -> 2988.648 | H17: =F17-G17 -> 26897.832 | I17: ='Cash Flow'!$E$21 -> 11207.43 | J17: =('Cash Flow'!$E$21-E17*Assumptions!$C$54)/F17 -> 0.2328125 | K17: =IFERROR(AVERAGE('Cash Flow'!$E$21-E17*Assumptions!$C$54,'Cash Flow'!$F$21-E17*Assumptions!$C$54,'Cash Flow'!$G$21+PMT(Assumptions!$C$54/12,Assumptions!$C$56*12,E17)*12,'Cash Flow'!$H$21+PMT(Assumptions!$C$54/12,Assumptions!$C$56*12,E17)*12,'Cash Flow'!$I$21+PMT(Assumptions!$C$54/12,Assumptions!$C$56*12,E17)*12)/F17,"-") -> 0.238062 | L17: =IFERROR(IRR(N17:S17),"n/a") -> 0.50796585 | M17: =IFERROR((SUM(O17:S17)+N17)/(-N17)+1,"n/a") -> 5.8212201 | N17: =-F17 -> -29886.48 | O17: ='Cash Flow'!$E$21-E17*Assumptions!$C$54 -> 6957.9461 | P17: ='Cash Flow'!$F$21-E17*Assumptions!$C$54 -> 7294.169 | Q17: ='Cash Flow'!$G$21+PMT(Assumptions!$C$54/12,Assumptions!$C$56*12,E17)*12 -> 6842.4645 | R17: ='Cash Flow'!$H$21+PMT(Assumptions!$C$54/12,Assumptions!$C$56*12,E17)*12 -> 7105.4822 | S17: ='Cash Flow'!$I$21+PMT(Assumptions!$C$54/12,Assumptions!$C$56*12,E17)*12+('Cash Flow'!$I$21/Assumptions!$C$63)*(1-Assumptions!$C$64)-(E17+CUMPRINC(Assumptions!$C$54/12,Assumptions!$C$56*12,E17,1,MIN(Assumptions!$C$62*12-Assumptions!$C$55,Assumptions!$C$56*12),0)) -> 145775.72
A18: =IF(ABS(C18-Assumptions!$C$7)<C18*0.02,"★ BASE",IF(Assumptions!$C$7>C18,"▼ OVERPRICE","▲ UPSIDE")) -> ▼ OVERPRICE | B18: 0.13 | C18: ='Cash Flow'!$E$21/B18 -> 86211 | D18: =Assumptions!$C$52 -> 0.7 | E18: =C18*D18 -> 60347.7 | F18: =C18*(1+Assumptions!$C$8)+Assumptions!$C$36-E18 -> 27587.52 | G18: =F18*Assumptions!$C$67 -> 2758.752 | H18: =F18-G18 -> 24828.768 | I18: ='Cash Flow'!$E$21 -> 11207.43 | J18: =('Cash Flow'!$E$21-E18*Assumptions!$C$54)/F18 -> 0.2640625 | K18: =IFERROR(AVERAGE('Cash Flow'!$E$21-E18*Assumptions!$C$54,'Cash Flow'!$F$21-E18*Assumptions!$C$54,'Cash Flow'!$G$21+PMT(Assumptions!$C$54/12,Assumptions!$C$56*12,E18)*12,'Cash Flow'!$H$21+PMT(Assumptions!$C$54/12,Assumptions!$C$56*12,E18)*12,'Cash Flow'!$I$21+PMT(Assumptions!$C$54/12,Assumptions!$C$56*12,E18)*12)/F18,"-") -> 0.27093598 | L18: =IFERROR(IRR(N18:S18),"n/a") -> 0.55588641 | M18: =IFERROR((SUM(O18:S18)+N18)/(-N18)+1,"n/a") -> 6.5472598 | N18: =-F18 -> -27587.52 | O18: ='Cash Flow'!$E$21-E18*Assumptions!$C$54 -> 7284.8295 | P18: ='Cash Flow'!$F$21-E18*Assumptions!$C$54 -> 7621.0524 | Q18: ='Cash Flow'!$G$21+PMT(Assumptions!$C$54/12,Assumptions!$C$56*12,E18)*12 -> 7223.903 | R18: ='Cash Flow'!$H$21+PMT(Assumptions!$C$54/12,Assumptions!$C$56*12,E18)*12 -> 7486.9207 | S18: ='Cash Flow'!$I$21+PMT(Assumptions!$C$54/12,Assumptions!$C$56*12,E18)*12+('Cash Flow'!$I$21/Assumptions!$C$63)*(1-Assumptions!$C$64)-(E18+CUMPRINC(Assumptions!$C$54/12,Assumptions!$C$56*12,E18,1,MIN(Assumptions!$C$62*12-Assumptions!$C$55,Assumptions!$C$56*12),0)) -> 151005.95
A19: =IF(ABS(C19-Assumptions!$C$7)<C19*0.02,"★ BASE",IF(Assumptions!$C$7>C19,"▼ OVERPRICE","▲ UPSIDE")) -> ▼ OVERPRICE | B19: 0.14 | C19: ='Cash Flow'!$E$21/B19 -> 80053.071 | D19: =Assumptions!$C$52 -> 0.7 | E19: =C19*D19 -> 56037.15 | F19: =C19*(1+Assumptions!$C$8)+Assumptions!$C$36-E19 -> 25616.983 | G19: =F19*Assumptions!$C$67 -> 2561.6983 | H19: =F19-G19 -> 23055.285 | I19: ='Cash Flow'!$E$21 -> 11207.43 | J19: =('Cash Flow'!$E$21-E19*Assumptions!$C$54)/F19 -> 0.2953125 | K19: =IFERROR(AVERAGE('Cash Flow'!$E$21-E19*Assumptions!$C$54,'Cash Flow'!$F$21-E19*Assumptions!$C$54,'Cash Flow'!$G$21+PMT(Assumptions!$C$54/12,Assumptions!$C$56*12,E19)*12,'Cash Flow'!$H$21+PMT(Assumptions!$C$54/12,Assumptions!$C$56*12,E19)*12,'Cash Flow'!$I$21+PMT(Assumptions!$C$54/12,Assumptions!$C$56*12,E19)*12)/F19,"-") -> 0.30380996 | L19: =IFERROR(IRR(N19:S19),"n/a") -> 0.60104114 | M19: =IFERROR((SUM(O19:S19)+N19)/(-N19)+1,"n/a") -> 7.2732994 | N19: =-F19 -> -25616.983 | O19: ='Cash Flow'!$E$21-E19*Assumptions!$C$54 -> 7565.0153 | P19: ='Cash Flow'!$F$21-E19*Assumptions!$C$54 -> 7901.2382 | Q19: ='Cash Flow'!$G$21+PMT(Assumptions!$C$54/12,Assumptions!$C$56*12,E19)*12 -> 7550.8503 | R19: ='Cash Flow'!$H$21+PMT(Assumptions!$C$54/12,Assumptions!$C$56*12,E19)*12 -> 7813.868 | S19: ='Cash Flow'!$I$21+PMT(Assumptions!$C$54/12,Assumptions!$C$56*12,E19)*12+('Cash Flow'!$I$21/Assumptions!$C$63)*(1-Assumptions!$C$64)-(E19+CUMPRINC(Assumptions!$C$54/12,Assumptions!$C$56*12,E19,1,MIN(Assumptions!$C$62*12-Assumptions!$C$55,Assumptions!$C$56*12),0)) -> 155489.02
A20: =IF(ABS(C20-Assumptions!$C$7)<C20*0.02,"★ BASE",IF(Assumptions!$C$7>C20,"▼ OVERPRICE","▲ UPSIDE")) -> ▼ OVERPRICE | B20: 0.15 | C20: ='Cash Flow'!$E$21/B20 -> 74716.2 | D20: =Assumptions!$C$52 -> 0.7 | E20: =C20*D20 -> 52301.34 | F20: =C20*(1+Assumptions!$C$8)+Assumptions!$C$36-E20 -> 23909.184 | G20: =F20*Assumptions!$C$67 -> 2390.9184 | H20: =F20-G20 -> 21518.266 | I20: ='Cash Flow'!$E$21 -> 11207.43 | J20: =('Cash Flow'!$E$21-E20*Assumptions!$C$54)/F20 -> 0.3265625 | K20: =IFERROR(AVERAGE('Cash Flow'!$E$21-E20*Assumptions!$C$54,'Cash Flow'!$F$21-E20*Assumptions!$C$54,'Cash Flow'!$G$21+PMT(Assumptions!$C$54/12,Assumptions!$C$56*12,E20)*12,'Cash Flow'!$H$21+PMT(Assumptions!$C$54/12,Assumptions!$C$56*12,E20)*12,'Cash Flow'!$I$21+PMT(Assumptions!$C$54/12,Assumptions!$C$56*12,E20)*12)/F20,"-") -> 0.33668393 | L20: =IFERROR(IRR(N20:S20),"n/a") -> 0.64392781 | M20: =IFERROR((SUM(O20:S20)+N20)/(-N20)+1,"n/a") -> 7.9993391 | N20: =-F20 -> -23909.184 | O20: ='Cash Flow'!$E$21-E20*Assumptions!$C$54 -> 7807.8429 | P20: ='Cash Flow'!$F$21-E20*Assumptions!$C$54 -> 8144.0658 | Q20: ='Cash Flow'!$G$21+PMT(Assumptions!$C$54/12,Assumptions!$C$56*12,E20)*12 -> 7834.2046 | R20: ='Cash Flow'!$H$21+PMT(Assumptions!$C$54/12,Assumptions!$C$56*12,E20)*12 -> 8097.2223 | S20: ='Cash Flow'!$I$21+PMT(Assumptions!$C$54/12,Assumptions!$C$56*12,E20)*12+('Cash Flow'!$I$21/Assumptions!$C$63)*(1-Assumptions!$C$64)-(E20+CUMPRINC(Assumptions!$C$54/12,Assumptions!$C$56*12,E20,1,MIN(Assumptions!$C$62*12-Assumptions!$C$55,Assumptions!$C$56*12),0)) -> 159374.33
B23: SENSITIVITY: LEVERED IRR — Entry Cap Rate (rows) × Exit Cap Rate (columns)
B24: 🟢 ≥ IRR target 🟡 within 3% below 🔴 below | Yellow column = live exit cap from Assumptions
B25: Entry Cap \ Exit Cap | C25: 0.04 | D25: 0.045 | E25: 0.05 | F25: 0.055 | G25: 0.06 | H25: 0.065 | I25: 0.07 | J25: 0.075 | K25: 0.08
B26: 0.05 | C26: =IFERROR(IRR(N300:S300),"n/a") -> 0.16717343 | D26: =IFERROR(IRR(N301:S301),"n/a") -> 0.11055108 | E26: =IFERROR(IRR(N302:S302),"n/a") -> 0.055040532 | F26: =IFERROR(IRR(N303:S303),"n/a") -> -0.001179772 | G26: =IFERROR(IRR(N304:S304),"n/a") -> -0.060314325 | H26: =IFERROR(IRR(N305:S305),"n/a") -> -0.12568884 | I26: =IFERROR(IRR(N306:S306),"n/a") -> -0.2037351 | J26: =IFERROR(IRR(N307:S307),"n/a") -> -0.31238232 | K26: =IFERROR(IRR(N308:S308),"n/a") -> -0.65738393 | V26: ='Cash Flow'!$I$21+PMT(Assumptions!$C$54/12,Assumptions!$C$56*12,E10)*12+('Cash Flow'!$I$21/0.04)*(1-Assumptions!$C$64)-(E10+CUMPRINC(Assumptions!$C$54/12,Assumptions!$C$56*12,E10,1,MIN(Assumptions!$C$62*12-Assumptions!$C$55,Assumptions!$C$56*12),0)) -> 151303.39 | W26: ='Cash Flow'!$I$21+PMT(Assumptions!$C$54/12,Assumptions!$C$56*12,E10)*12+('Cash Flow'!$I$21/0.045)*(1-Assumptions!$C$64)-(E10+CUMPRINC(Assumptions!$C$54/12,Assumptions!$C$56*12,E10,1,MIN(Assumptions!$C$62*12-Assumptions!$C$55,Assumptions!$C$56*12),0)) -> 117730.72 | X26: ='Cash Flow'!$I$21+PMT(Assumptions!$C$54/12,Assumptions!$C$56*12,E10)*12+('Cash Flow'!$I$21/0.05)*(1-Assumptions!$C$64)-(E10+CUMPRINC(Assumptions!$C$54/12,Assumptions!$C$56*12,E10,1,MIN(Assumptions!$C$62*12-Assumptions!$C$55,Assumptions!$C$56*12),0)) -> 90872.592 | Y26: ='Cash Flow'!$I$21+PMT(Assumptions!$C$54/12,Assumptions!$C$56*12,E10)*12+('Cash Flow'!$I$21/0.055)*(1-Assumptions!$C$64)-(E10+CUMPRINC(Assumptions!$C$54/12,Assumptions!$C$56*12,E10,1,MIN(Assumptions!$C$62*12-Assumptions!$C$55,Assumptions!$C$56*12),0)) -> 68897.757 | Z26: ='Cash Flow'!$I$21+PMT(Assumptions!$C$54/12,Assumptions!$C$56*12,E10)*12+('Cash Flow'!$I$21/0.06)*(1-Assumptions!$C$64)-(E10+CUMPRINC(Assumptions!$C$54/12,Assumptions!$C$56*12,E10,1,MIN(Assumptions!$C$62*12-Assumptions!$C$55,Assumptions!$C$56*12),0)) -> 50585.394 | AA26: ='Cash Flow'!$I$21+PMT(Assumptions!$C$54/12,Assumptions!$C$56*12,E10)*12+('Cash Flow'!$I$21/0.065)*(1-Assumptions!$C$64)-(E10+CUMPRINC(Assumptions!$C$54/12,Assumptions!$C$56*12,E10,1,MIN(Assumptions!$C$62*12-Assumptions!$C$55,Assumptions!$C$56*12),0)) -> 35090.318 | AB26: ='Cash Flow'!$I$21+PMT(Assumptions!$C$54/12,Assumptions!$C$56*12,E10)*12+('Cash Flow'!$I$21/0.07)*(1-Assumptions!$C$64)-(E10+CUMPRINC(Assumptions!$C$54/12,Assumptions!$C$56*12,E10,1,MIN(Assumptions!$C$62*12-Assumptions!$C$55,Assumptions!$C$56*12),0)) -> 21808.824 | AC26: ='Cash Flow'!$I$21+PMT(Assumptions!$C$54/12,Assumptions!$C$56*12,E10)*12+('Cash Flow'!$I$21/0.075)*(1-Assumptions!$C$64)-(E10+CUMPRINC(Assumptions!$C$54/12,Assumptions!$C$56*12,E10,1,MIN(Assumptions!$C$62*12-Assumptions!$C$55,Assumptions!$C$56*12),0)) -> 10298.196 | AD26: ='Cash Flow'!$I$21+PMT(Assumptions!$C$54/12,Assumptions!$C$56*12,E10)*12+('Cash Flow'!$I$21/0.08)*(1-Assumptions!$C$64)-(E10+CUMPRINC(Assumptions!$C$54/12,Assumptions!$C$56*12,E10,1,MIN(Assumptions!$C$62*12-Assumptions!$C$55,Assumptions!$C$56*12),0)) -> 226.39704
B27: 0.06 | C27: =IFERROR(IRR(N309:S309),"n/a") -> 0.27009247 | D27: =IFERROR(IRR(N310:S310),"n/a") -> 0.22053128 | E27: =IFERROR(IRR(N311:S311),"n/a") -> 0.17391255 | F27: =IFERROR(IRR(N312:S312),"n/a") -> 0.12913369 | G27: =IFERROR(IRR(N313:S313),"n/a") -> 0.085245031 | H27: =IFERROR(IRR(N314:S314),"n/a") -> 0.041328086 | I27: =IFERROR(IRR(N315:S315),"n/a") -> -0.0036291451 | J27: =IFERROR(IRR(N316:S316),"n/a") -> -0.050908901 | K27: =IFERROR(IRR(N317:S317),"n/a") -> -0.10239377 | V27: ='Cash Flow'!$I$21+PMT(Assumptions!$C$54/12,Assumptions!$C$56*12,E11)*12+('Cash Flow'!$I$21/0.04)*(1-Assumptions!$C$64)-(E11+CUMPRINC(Assumptions!$C$54/12,Assumptions!$C$56*12,E11,1,MIN(Assumptions!$C$62*12-Assumptions!$C$55,Assumptions!$C$56*12),0)) -> 178500.62 | W27: ='Cash Flow'!$I$21+PMT(Assumptions!$C$54/12,Assumptions!$C$56*12,E11)*12+('Cash Flow'!$I$21/0.045)*(1-Assumptions!$C$64)-(E11+CUMPRINC(Assumptions!$C$54/12,Assumptions!$C$56*12,E11,1,MIN(Assumptions!$C$62*12-Assumptions!$C$55,Assumptions!$C$56*12),0)) -> 144927.96 | X27: ='Cash Flow'!$I$21+PMT(Assumptions!$C$54/12,Assumptions!$C$56*12,E11)*12+('Cash Flow'!$I$21/0.05)*(1-Assumptions!$C$64)-(E11+CUMPRINC(Assumptions!$C$54/12,Assumptions!$C$56*12,E11,1,MIN(Assumptions!$C$62*12-Assumptions!$C$55,Assumptions!$C$56*12),0)) -> 118069.83 | Y27: ='Cash Flow'!$I$21+PMT(Assumptions!$C$54/12,Assumptions!$C$56*12,E11)*12+('Cash Flow'!$I$21/0.055)*(1-Assumptions!$C$64)-(E11+CUMPRINC(Assumptions!$C$54/12,Assumptions!$C$56*12,E11,1,MIN(Assumptions!$C$62*12-Assumptions!$C$55,Assumptions!$C$56*12),0)) -> 96094.992 | Z27: ='Cash Flow'!$I$21+PMT(Assumptions!$C$54/12,Assumptions!$C$56*12,E11)*12+('Cash Flow'!$I$21/0.06)*(1-Assumptions!$C$64)-(E11+CUMPRINC(Assumptions!$C$54/12,Assumptions!$C$56*12,E11,1,MIN(Assumptions!$C$62*12-Assumptions!$C$55,Assumptions!$C$56*12),0)) -> 77782.629 | AA27: ='Cash Flow'!$I$21+PMT(Assumptions!$C$54/12,Assumptions!$C$56*12,E11)*12+('Cash Flow'!$I$21/0.065)*(1-Assumptions!$C$64)-(E11+CUMPRINC(Assumptions!$C$54/12,Assumptions!$C$56*12,E11,1,MIN(Assumptions!$C$62*12-Assumptions!$C$55,Assumptions!$C$56*12),0)) -> 62287.553 | AB27: ='Cash Flow'!$I$21+PMT(Assumptions!$C$54/12,Assumptions!$C$56*12,E11)*12+('Cash Flow'!$I$21/0.07)*(1-Assumptions!$C$64)-(E11+CUMPRINC(Assumptions!$C$54/12,Assumptions!$C$56*12,E11,1,MIN(Assumptions!$C$62*12-Assumptions!$C$55,Assumptions!$C$56*12),0)) -> 49006.059 | AC27: ='Cash Flow'!$I$21+PMT(Assumptions!$C$54/12,Assumptions!$C$56*12,E11)*12+('Cash Flow'!$I$21/0.075)*(1-Assumptions!$C$64)-(E11+CUMPRINC(Assumptions!$C$54/12,Assumptions!$C$56*12,E11,1,MIN(Assumptions!$C$62*12-Assumptions!$C$55,Assumptions!$C$56*12),0)) -> 37495.432 | AD27: ='Cash Flow'!$I$21+PMT(Assumptions!$C$54/12,Assumptions!$C$56*12,E11)*12+('Cash Flow'!$I$21/0.08)*(1-Assumptions!$C$64)-(E11+CUMPRINC(Assumptions!$C$54/12,Assumptions!$C$56*12,E11,1,MIN(Assumptions!$C$62*12-Assumptions!$C$55,Assumptions!$C$56*12),0)) -> 27423.632
B28: 0.07 | C28: =IFERROR(IRR(N318:S318),"n/a") -> 0.35323643 | D28: =IFERROR(IRR(N319:S319),"n/a") -> 0.30729514 | E28: =IFERROR(IRR(N320:S320),"n/a") -> 0.26498129 | F28: =IFERROR(IRR(N321:S321),"n/a") -> 0.22532956 | G28: =IFERROR(IRR(N322:S322),"n/a") -> 0.18759618 | H28: =IFERROR(IRR(N323:S323),"n/a") -> 0.15117178 | I28: =IFERROR(IRR(N324:S324),"n/a") -> 0.11552186 | J28: =IFERROR(IRR(N325:S325),"n/a") -> 0.080139992 | K28: =IFERROR(IRR(N326:S326),"n/a") -> 0.044503098 | V28: ='Cash Flow'!$I$21+PMT(Assumptions!$C$54/12,Assumptions!$C$56*12,E12)*12+('Cash Flow'!$I$21/0.04)*(1-Assumptions!$C$64)-(E12+CUMPRINC(Assumptions!$C$54/12,Assumptions!$C$56*12,E12,1,MIN(Assumptions!$C$62*12-Assumptions!$C$55,Assumptions!$C$56*12),0)) -> 197927.22 | W28: ='Cash Flow'!$I$21+PMT(Assumptions!$C$54/12,Assumptions!$C$56*12,E12)*12+('Cash Flow'!$I$21/0.045)*(1-Assumptions!$C$64)-(E12+CUMPRINC(Assumptions!$C$54/12,Assumptions!$C$56*12,E12,1,MIN(Assumptions!$C$62*12-Assumptions!$C$55,Assumptions!$C$56*12),0)) -> 164354.56 | X28: ='Cash Flow'!$I$21+PMT(Assumptions!$C$54/12,Assumptions!$C$56*12,E12)*12+('Cash Flow'!$I$21/0.05)*(1-Assumptions!$C$64)-(E12+CUMPRINC(Assumptions!$C$54/12,Assumptions!$C$56*12,E12,1,MIN(Assumptions!$C$62*12-Assumptions!$C$55,Assumptions!$C$56*12),0)) -> 137496.42 | Y28: ='Cash Flow'!$I$21+PMT(Assumptions!$C$54/12,Assumptions!$C$56*12,E12)*12+('Cash Flow'!$I$21/0.055)*(1-Assumptions!$C$64)-(E12+CUMPRINC(Assumptions!$C$54/12,Assumptions!$C$56*12,E12,1,MIN(Assumptions!$C$62*12-Assumptions!$C$55,Assumptions!$C$56*12),0)) -> 115521.59 | Z28: ='Cash Flow'!$I$21+PMT(Assumptions!$C$54/12,Assumptions!$C$56*12,E12)*12+('Cash Flow'!$I$21/0.06)*(1-Assumptions!$C$64)-(E12+CUMPRINC(Assumptions!$C$54/12,Assumptions!$C$56*12,E12,1,MIN(Assumptions!$C$62*12-Assumptions!$C$55,Assumptions!$C$56*12),0)) -> 97209.226 | AA28: ='Cash Flow'!$I$21+PMT(Assumptions!$C$54/12,Assumptions!$C$56*12,E12)*12+('Cash Flow'!$I$21/0.065)*(1-Assumptions!$C$64)-(E12+CUMPRINC(Assumptions!$C$54/12,Assumptions!$C$56*12,E12,1,MIN(Assumptions!$C$62*12-Assumptions!$C$55,Assumptions!$C$56*12),0)) -> 81714.15 | AB28: ='Cash Flow'!$I$21+PMT(Assumptions!$C$54/12,Assumptions!$C$56*12,E12)*12+('Cash Flow'!$I$21/0.07)*(1-Assumptions!$C$64)-(E12+CUMPRINC(Assumptions!$C$54/12,Assumptions!$C$56*12,E12,1,MIN(Assumptions!$C$62*12-Assumptions!$C$55,Assumptions!$C$56*12),0)) -> 68432.656 | AC28: ='Cash Flow'!$I$21+PMT(Assumptions!$C$54/12,Assumptions!$C$56*12,E12)*12+('Cash Flow'!$I$21/0.075)*(1-Assumptions!$C$64)-(E12+CUMPRINC(Assumptions!$C$54/12,Assumptions!$C$56*12,E12,1,MIN(Assumptions!$C$62*12-Assumptions!$C$55,Assumptions!$C$56*12),0)) -> 56922.028 | AD28: ='Cash Flow'!$I$21+PMT(Assumptions!$C$54/12,Assumptions!$C$56*12,E12)*12+('Cash Flow'!$I$21/0.08)*(1-Assumptions!$C$64)-(E12+CUMPRINC(Assumptions!$C$54/12,Assumptions!$C$56*12,E12,1,MIN(Assumptions!$C$62*12-Assumptions!$C$55,Assumptions!$C$56*12),0)) -> 46850.229
B29: 0.08 | C29: =IFERROR(IRR(N327:S327),"n/a") -> 0.42429447 | D29: =IFERROR(IRR(N328:S328),"n/a") -> 0.38050776 | E29: =IFERROR(IRR(N329:S329),"n/a") -> 0.34069345 | F29: =IFERROR(IRR(N330:S330),"n/a") -> 0.30391849 | G29: =IFERROR(IRR(N331:S331),"n/a") -> 0.26949006 | H29: =IFERROR(IRR(N332:S332),"n/a") -> 0.23687185 | I29: =IFERROR(IRR(N333:S333),"n/a") -> 0.20563115 | J29: =IFERROR(IRR(N334:S334),"n/a") -> 0.17540352 | K29: =IFERROR(IRR(N335:S335),"n/a") -> 0.14586718 | V29: ='Cash Flow'!$I$21+PMT(Assumptions!$C$54/12,Assumptions!$C$56*12,E13)*12+('Cash Flow'!$I$21/0.04)*(1-Assumptions!$C$64)-(E13+CUMPRINC(Assumptions!$C$54/12,Assumptions!$C$56*12,E13,1,MIN(Assumptions!$C$62*12-Assumptions!$C$55,Assumptions!$C$56*12),0)) -> 212497.17 | W29: ='Cash Flow'!$I$21+PMT(Assumptions!$C$54/12,Assumptions!$C$56*12,E13)*12+('Cash Flow'!$I$21/0.045)*(1-Assumptions!$C$64)-(E13+CUMPRINC(Assumptions!$C$54/12,Assumptions!$C$56*12,E13,1,MIN(Assumptions!$C$62*12-Assumptions!$C$55,Assumptions!$C$56*12),0)) -> 178924.5 | X29: ='Cash Flow'!$I$21+PMT(Assumptions!$C$54/12,Assumptions!$C$56*12,E13)*12+('Cash Flow'!$I$21/0.05)*(1-Assumptions!$C$64)-(E13+CUMPRINC(Assumptions!$C$54/12,Assumptions!$C$56*12,E13,1,MIN(Assumptions!$C$62*12-Assumptions!$C$55,Assumptions!$C$56*12),0)) -> 152066.37 | Y29: ='Cash Flow'!$I$21+PMT(Assumptions!$C$54/12,Assumptions!$C$56*12,E13)*12+('Cash Flow'!$I$21/0.055)*(1-Assumptions!$C$64)-(E13+CUMPRINC(Assumptions!$C$54/12,Assumptions!$C$56*12,E13,1,MIN(Assumptions!$C$62*12-Assumptions!$C$55,Assumptions!$C$56*12),0)) -> 130091.54 | Z29: ='Cash Flow'!$I$21+PMT(Assumptions!$C$54/12,Assumptions!$C$56*12,E13)*12+('Cash Flow'!$I$21/0.06)*(1-Assumptions!$C$64)-(E13+CUMPRINC(Assumptions!$C$54/12,Assumptions!$C$56*12,E13,1,MIN(Assumptions!$C$62*12-Assumptions!$C$55,Assumptions!$C$56*12),0)) -> 111779.17 | AA29: ='Cash Flow'!$I$21+PMT(Assumptions!$C$54/12,Assumptions!$C$56*12,E13)*12+('Cash Flow'!$I$21/0.065)*(1-Assumptions!$C$64)-(E13+CUMPRINC(Assumptions!$C$54/12,Assumptions!$C$56*12,E13,1,MIN(Assumptions!$C$62*12-Assumptions!$C$55,Assumptions!$C$56*12),0)) -> 96284.097 | AB29: ='Cash Flow'!$I$21+PMT(Assumptions!$C$54/12,Assumptions!$C$56*12,E13)*12+('Cash Flow'!$I$21/0.07)*(1-Assumptions!$C$64)-(E13+CUMPRINC(Assumptions!$C$54/12,Assumptions!$C$56*12,E13,1,MIN(Assumptions!$C$62*12-Assumptions!$C$55,Assumptions!$C$56*12),0)) -> 83002.603 | AC29: ='Cash Flow'!$I$21+PMT(Assumptions!$C$54/12,Assumptions!$C$56*12,E13)*12+('Cash Flow'!$I$21/0.075)*(1-Assumptions!$C$64)-(E13+CUMPRINC(Assumptions!$C$54/12,Assumptions!$C$56*12,E13,1,MIN(Assumptions!$C$62*12-Assumptions!$C$55,Assumptions!$C$56*12),0)) -> 71491.975 | AD29: ='Cash Flow'!$I$21+PMT(Assumptions!$C$54/12,Assumptions!$C$56*12,E13)*12+('Cash Flow'!$I$21/0.08)*(1-Assumptions!$C$64)-(E13+CUMPRINC(Assumptions!$C$54/12,Assumptions!$C$56*12,E13,1,MIN(Assumptions!$C$62*12-Assumptions!$C$55,Assumptions!$C$56*12),0)) -> 61420.176
B30: 0.09 | C30: =IFERROR(IRR(N336:S336),"n/a") -> 0.48714091 | D30: =IFERROR(IRR(N337:S337),"n/a") -> 0.44475804 | E30: =IFERROR(IRR(N338:S338),"n/a") -> 0.40655558 | F30: =IFERROR(IRR(N339:S339),"n/a") -> 0.37160437 | G30: =IFERROR(IRR(N340:S340),"n/a") -> 0.33922408 | H30: =IFERROR(IRR(N341:S341),"n/a") -> 0.30889894 | I30: =IFERROR(IRR(N342:S342),"n/a") -> 0.28022541 | J30: =IFERROR(IRR(N343:S343),"n/a") -> 0.25287827 | K30: =IFERROR(IRR(N344:S344),"n/a") -> 0.22658749 | V30: ='Cash Flow'!$I$21+PMT(Assumptions!$C$54/12,Assumptions!$C$56*12,E14)*12+('Cash Flow'!$I$21/0.04)*(1-Assumptions!$C$64)-(E14+CUMPRINC(Assumptions!$C$54/12,Assumptions!$C$56*12,E14,1,MIN(Assumptions!$C$62*12-Assumptions!$C$55,Assumptions!$C$56*12),0)) -> 223829.35 | W30: ='Cash Flow'!$I$21+PMT(Assumptions!$C$54/12,Assumptions!$C$56*12,E14)*12+('Cash Flow'!$I$21/0.045)*(1-Assumptions!$C$64)-(E14+CUMPRINC(Assumptions!$C$54/12,Assumptions!$C$56*12,E14,1,MIN(Assumptions!$C$62*12-Assumptions!$C$55,Assumptions!$C$56*12),0)) -> 190256.68 | X30: ='Cash Flow'!$I$21+PMT(Assumptions!$C$54/12,Assumptions!$C$56*12,E14)*12+('Cash Flow'!$I$21/0.05)*(1-Assumptions!$C$64)-(E14+CUMPRINC(Assumptions!$C$54/12,Assumptions!$C$56*12,E14,1,MIN(Assumptions!$C$62*12-Assumptions!$C$55,Assumptions!$C$56*12),0)) -> 163398.55 | Y30: ='Cash Flow'!$I$21+PMT(Assumptions!$C$54/12,Assumptions!$C$56*12,E14)*12+('Cash Flow'!$I$21/0.055)*(1-Assumptions!$C$64)-(E14+CUMPRINC(Assumptions!$C$54/12,Assumptions!$C$56*12,E14,1,MIN(Assumptions!$C$62*12-Assumptions!$C$55,Assumptions!$C$56*12),0)) -> 141423.72 | Z30: ='Cash Flow'!$I$21+PMT(Assumptions!$C$54/12,Assumptions!$C$56*12,E14)*12+('Cash Flow'!$I$21/0.06)*(1-Assumptions!$C$64)-(E14+CUMPRINC(Assumptions!$C$54/12,Assumptions!$C$56*12,E14,1,MIN(Assumptions!$C$62*12-Assumptions!$C$55,Assumptions!$C$56*12),0)) -> 123111.35 | AA30: ='Cash Flow'!$I$21+PMT(Assumptions!$C$54/12,Assumptions!$C$56*12,E14)*12+('Cash Flow'!$I$21/0.065)*(1-Assumptions!$C$64)-(E14+CUMPRINC(Assumptions!$C$54/12,Assumptions!$C$56*12,E14,1,MIN(Assumptions!$C$62*12-Assumptions!$C$55,Assumptions!$C$56*12),0)) -> 107616.28 | AB30: ='Cash Flow'!$I$21+PMT(Assumptions!$C$54/12,Assumptions!$C$56*12,E14)*12+('Cash Flow'!$I$21/0.07)*(1-Assumptions!$C$64)-(E14+CUMPRINC(Assumptions!$C$54/12,Assumptions!$C$56*12,E14,1,MIN(Assumptions!$C$62*12-Assumptions!$C$55,Assumptions!$C$56*12),0)) -> 94334.784 | AC30: ='Cash Flow'!$I$21+PMT(Assumptions!$C$54/12,Assumptions!$C$56*12,E14)*12+('Cash Flow'!$I$21/0.075)*(1-Assumptions!$C$64)-(E14+CUMPRINC(Assumptions!$C$54/12,Assumptions!$C$56*12,E14,1,MIN(Assumptions!$C$62*12-Assumptions!$C$55,Assumptions!$C$56*12),0)) -> 82824.157 | AD30: ='Cash Flow'!$I$21+PMT(Assumptions!$C$54/12,Assumptions!$C$56*12,E14)*12+('Cash Flow'!$I$21/0.08)*(1-Assumptions!$C$64)-(E14+CUMPRINC(Assumptions!$C$54/12,Assumptions!$C$56*12,E14,1,MIN(Assumptions!$C$62*12-Assumptions!$C$55,Assumptions!$C$56*12),0)) -> 72752.357
B31: 0.1 | C31: =IFERROR(IRR(N345:S345),"n/a") -> 0.54402162 | D31: =IFERROR(IRR(N346:S346),"n/a") -> 0.50261227 | E31: =IFERROR(IRR(N347:S347),"n/a") -> 0.46552481 | F31: =IFERROR(IRR(N348:S348),"n/a") -> 0.43182465 | G31: =IFERROR(IRR(N349:S349),"n/a") -> 0.40083165 | H31: =IFERROR(IRR(N350:S350),"n/a") -> 0.37203462 | I31: =IFERROR(IRR(N351:S351),"n/a") -> 0.34503857 | J31: =IFERROR(IRR(N352:S352),"n/a") -> 0.31953064 | K31: =IFERROR(IRR(N353:S353),"n/a") -> 0.29525732 | V31: ='Cash Flow'!$I$21+PMT(Assumptions!$C$54/12,Assumptions!$C$56*12,E15)*12+('Cash Flow'!$I$21/0.04)*(1-Assumptions!$C$64)-(E15+CUMPRINC(Assumptions!$C$54/12,Assumptions!$C$56*12,E15,1,MIN(Assumptions!$C$62*12-Assumptions!$C$55,Assumptions!$C$56*12),0)) -> 232895.09 | W31: ='Cash Flow'!$I$21+PMT(Assumptions!$C$54/12,Assumptions!$C$56*12,E15)*12+('Cash Flow'!$I$21/0.045)*(1-Assumptions!$C$64)-(E15+CUMPRINC(Assumptions!$C$54/12,Assumptions!$C$56*12,E15,1,MIN(Assumptions!$C$62*12-Assumptions!$C$55,Assumptions!$C$56*12),0)) -> 199322.43 | X31: ='Cash Flow'!$I$21+PMT(Assumptions!$C$54/12,Assumptions!$C$56*12,E15)*12+('Cash Flow'!$I$21/0.05)*(1-Assumptions!$C$64)-(E15+CUMPRINC(Assumptions!$C$54/12,Assumptions!$C$56*12,E15,1,MIN(Assumptions!$C$62*12-Assumptions!$C$55,Assumptions!$C$56*12),0)) -> 172464.3 | Y31: ='Cash Flow'!$I$21+PMT(Assumptions!$C$54/12,Assumptions!$C$56*12,E15)*12+('Cash Flow'!$I$21/0.055)*(1-Assumptions!$C$64)-(E15+CUMPRINC(Assumptions!$C$54/12,Assumptions!$C$56*12,E15,1,MIN(Assumptions!$C$62*12-Assumptions!$C$55,Assumptions!$C$56*12),0)) -> 150489.46 | Z31: ='Cash Flow'!$I$21+PMT(Assumptions!$C$54/12,Assumptions!$C$56*12,E15)*12+('Cash Flow'!$I$21/0.06)*(1-Assumptions!$C$64)-(E15+CUMPRINC(Assumptions!$C$54/12,Assumptions!$C$56*12,E15,1,MIN(Assumptions!$C$62*12-Assumptions!$C$55,Assumptions!$C$56*12),0)) -> 132177.1 | AA31: ='Cash Flow'!$I$21+PMT(Assumptions!$C$54/12,Assumptions!$C$56*12,E15)*12+('Cash Flow'!$I$21/0.065)*(1-Assumptions!$C$64)-(E15+CUMPRINC(Assumptions!$C$54/12,Assumptions!$C$56*12,E15,1,MIN(Assumptions!$C$62*12-Assumptions!$C$55,Assumptions!$C$56*12),0)) -> 116682.02 | AB31: ='Cash Flow'!$I$21+PMT(Assumptions!$C$54/12,Assumptions!$C$56*12,E15)*12+('Cash Flow'!$I$21/0.07)*(1-Assumptions!$C$64)-(E15+CUMPRINC(Assumptions!$C$54/12,Assumptions!$C$56*12,E15,1,MIN(Assumptions!$C$62*12-Assumptions!$C$55,Assumptions!$C$56*12),0)) -> 103400.53 | AC31: ='Cash Flow'!$I$21+PMT(Assumptions!$C$54/12,Assumptions!$C$56*12,E15)*12+('Cash Flow'!$I$21/0.075)*(1-Assumptions!$C$64)-(E15+CUMPRINC(Assumptions!$C$54/12,Assumptions!$C$56*12,E15,1,MIN(Assumptions!$C$62*12-Assumptions!$C$55,Assumptions!$C$56*12),0)) -> 91889.902 | AD31: ='Cash Flow'!$I$21+PMT(Assumptions!$C$54/12,Assumptions!$C$56*12,E15)*12+('Cash Flow'!$I$21/0.08)*(1-Assumptions!$C$64)-(E15+CUMPRINC(Assumptions!$C$54/12,Assumptions!$C$56*12,E15,1,MIN(Assumptions!$C$62*12-Assumptions!$C$55,Assumptions!$C$56*12),0)) -> 81818.102
B32: 0.11 | C32: =IFERROR(IRR(N354:S354),"n/a") -> 0.59636302 | D32: =IFERROR(IRR(N355:S355),"n/a") -> 0.55566142 | E32: =IFERROR(IRR(N356:S356),"n/a") -> 0.51938628 | F32: =IFERROR(IRR(N357:S357),"n/a") -> 0.48659438 | G32: =IFERROR(IRR(N358:S358),"n/a") -> 0.45660127 | H32: =IFERROR(IRR(N359:S359),"n/a") -> 0.42889467 | I32: =IFERROR(IRR(N360:S360),"n/a") -> 0.4030809 | J32: =IFERROR(IRR(N361:S361),"n/a") -> 0.37885053 | K32: =IFERROR(IRR(N362:S362),"n/a") -> 0.35595538 | V32: ='Cash Flow'!$I$21+PMT(Assumptions!$C$54/12,Assumptions!$C$56*12,E16)*12+('Cash Flow'!$I$21/0.04)*(1-Assumptions!$C$64)-(E16+CUMPRINC(Assumptions!$C$54/12,Assumptions!$C$56*12,E16,1,MIN(Assumptions!$C$62*12-Assumptions!$C$55,Assumptions!$C$56*12),0)) -> 240312.52 | W32: ='Cash Flow'!$I$21+PMT(Assumptions!$C$54/12,Assumptions!$C$56*12,E16)*12+('Cash Flow'!$I$21/0.045)*(1-Assumptions!$C$64)-(E16+CUMPRINC(Assumptions!$C$54/12,Assumptions!$C$56*12,E16,1,MIN(Assumptions!$C$62*12-Assumptions!$C$55,Assumptions!$C$56*12),0)) -> 206739.86 | X32: ='Cash Flow'!$I$21+PMT(Assumptions!$C$54/12,Assumptions!$C$56*12,E16)*12+('Cash Flow'!$I$21/0.05)*(1-Assumptions!$C$64)-(E16+CUMPRINC(Assumptions!$C$54/12,Assumptions!$C$56*12,E16,1,MIN(Assumptions!$C$62*12-Assumptions!$C$55,Assumptions!$C$56*12),0)) -> 179881.72 | Y32: ='Cash Flow'!$I$21+PMT(Assumptions!$C$54/12,Assumptions!$C$56*12,E16)*12+('Cash Flow'!$I$21/0.055)*(1-Assumptions!$C$64)-(E16+CUMPRINC(Assumptions!$C$54/12,Assumptions!$C$56*12,E16,1,MIN(Assumptions!$C$62*12-Assumptions!$C$55,Assumptions!$C$56*12),0)) -> 157906.89 | Z32: ='Cash Flow'!$I$21+PMT(Assumptions!$C$54/12,Assumptions!$C$56*12,E16)*12+('Cash Flow'!$I$21/0.06)*(1-Assumptions!$C$64)-(E16+CUMPRINC(Assumptions!$C$54/12,Assumptions!$C$56*12,E16,1,MIN(Assumptions!$C$62*12-Assumptions!$C$55,Assumptions!$C$56*12),0)) -> 139594.53 | AA32: ='Cash Flow'!$I$21+PMT(Assumptions!$C$54/12,Assumptions!$C$56*12,E16)*12+('Cash Flow'!$I$21/0.065)*(1-Assumptions!$C$64)-(E16+CUMPRINC(Assumptions!$C$54/12,Assumptions!$C$56*12,E16,1,MIN(Assumptions!$C$62*12-Assumptions!$C$55,Assumptions!$C$56*12),0)) -> 124099.45 | AB32: ='Cash Flow'!$I$21+PMT(Assumptions!$C$54/12,Assumptions!$C$56*12,E16)*12+('Cash Flow'!$I$21/0.07)*(1-Assumptions!$C$64)-(E16+CUMPRINC(Assumptions!$C$54/12,Assumptions!$C$56*12,E16,1,MIN(Assumptions!$C$62*12-Assumptions!$C$55,Assumptions!$C$56*12),0)) -> 110817.96 | AC32: ='Cash Flow'!$I$21+PMT(Assumptions!$C$54/12,Assumptions!$C$56*12,E16)*12+('Cash Flow'!$I$21/0.075)*(1-Assumptions!$C$64)-(E16+CUMPRINC(Assumptions!$C$54/12,Assumptions!$C$56*12,E16,1,MIN(Assumptions!$C$62*12-Assumptions!$C$55,Assumptions!$C$56*12),0)) -> 99307.329 | AD32: ='Cash Flow'!$I$21+PMT(Assumptions!$C$54/12,Assumptions!$C$56*12,E16)*12+('Cash Flow'!$I$21/0.08)*(1-Assumptions!$C$64)-(E16+CUMPRINC(Assumptions!$C$54/12,Assumptions!$C$56*12,E16,1,MIN(Assumptions!$C$62*12-Assumptions!$C$55,Assumptions!$C$56*12),0)) -> 89235.53
B33: 0.12 | C33: =IFERROR(IRR(N363:S363),"n/a") -> 0.64513161 | D33: =IFERROR(IRR(N364:S364),"n/a") -> 0.60496474 | E33: =IFERROR(IRR(N365:S365),"n/a") -> 0.56930633 | F33: =IFERROR(IRR(N366:S366),"n/a") -> 0.53720349 | G33: =IFERROR(IRR(N367:S367),"n/a") -> 0.50796585 | H33: =IFERROR(IRR(N368:S368),"n/a") -> 0.4810778 | I33: =IFERROR(IRR(N369:S369),"n/a") -> 0.45614418 | J33: =IFERROR(IRR(N370:S370),"n/a") -> 0.43285555 | K33: =IFERROR(IRR(N371:S371),"n/a") -> 0.41096489 | V33: ='Cash Flow'!$I$21+PMT(Assumptions!$C$54/12,Assumptions!$C$56*12,E17)*12+('Cash Flow'!$I$21/0.04)*(1-Assumptions!$C$64)-(E17+CUMPRINC(Assumptions!$C$54/12,Assumptions!$C$56*12,E17,1,MIN(Assumptions!$C$62*12-Assumptions!$C$55,Assumptions!$C$56*12),0)) -> 246493.71 | W33: ='Cash Flow'!$I$21+PMT(Assumptions!$C$54/12,Assumptions!$C$56*12,E17)*12+('Cash Flow'!$I$21/0.045)*(1-Assumptions!$C$64)-(E17+CUMPRINC(Assumptions!$C$54/12,Assumptions!$C$56*12,E17,1,MIN(Assumptions!$C$62*12-Assumptions!$C$55,Assumptions!$C$56*12),0)) -> 212921.05 | X33: ='Cash Flow'!$I$21+PMT(Assumptions!$C$54/12,Assumptions!$C$56*12,E17)*12+('Cash Flow'!$I$21/0.05)*(1-Assumptions!$C$64)-(E17+CUMPRINC(Assumptions!$C$54/12,Assumptions!$C$56*12,E17,1,MIN(Assumptions!$C$62*12-Assumptions!$C$55,Assumptions!$C$56*12),0)) -> 186062.91 | Y33: ='Cash Flow'!$I$21+PMT(Assumptions!$C$54/12,Assumptions!$C$56*12,E17)*12+('Cash Flow'!$I$21/0.055)*(1-Assumptions!$C$64)-(E17+CUMPRINC(Assumptions!$C$54/12,Assumptions!$C$56*12,E17,1,MIN(Assumptions!$C$62*12-Assumptions!$C$55,Assumptions!$C$56*12),0)) -> 164088.08 | Z33: ='Cash Flow'!$I$21+PMT(Assumptions!$C$54/12,Assumptions!$C$56*12,E17)*12+('Cash Flow'!$I$21/0.06)*(1-Assumptions!$C$64)-(E17+CUMPRINC(Assumptions!$C$54/12,Assumptions!$C$56*12,E17,1,MIN(Assumptions!$C$62*12-Assumptions!$C$55,Assumptions!$C$56*12),0)) -> 145775.72 | AA33: ='Cash Flow'!$I$21+PMT(Assumptions!$C$54/12,Assumptions!$C$56*12,E17)*12+('Cash Flow'!$I$21/0.065)*(1-Assumptions!$C$64)-(E17+CUMPRINC(Assumptions!$C$54/12,Assumptions!$C$56*12,E17,1,MIN(Assumptions!$C$62*12-Assumptions!$C$55,Assumptions!$C$56*12),0)) -> 130280.64 | AB33: ='Cash Flow'!$I$21+PMT(Assumptions!$C$54/12,Assumptions!$C$56*12,E17)*12+('Cash Flow'!$I$21/0.07)*(1-Assumptions!$C$64)-(E17+CUMPRINC(Assumptions!$C$54/12,Assumptions!$C$56*12,E17,1,MIN(Assumptions!$C$62*12-Assumptions!$C$55,Assumptions!$C$56*12),0)) -> 116999.15 | AC33: ='Cash Flow'!$I$21+PMT(Assumptions!$C$54/12,Assumptions!$C$56*12,E17)*12+('Cash Flow'!$I$21/0.075)*(1-Assumptions!$C$64)-(E17+CUMPRINC(Assumptions!$C$54/12,Assumptions!$C$56*12,E17,1,MIN(Assumptions!$C$62*12-Assumptions!$C$55,Assumptions!$C$56*12),0)) -> 105488.52 | AD33: ='Cash Flow'!$I$21+PMT(Assumptions!$C$54/12,Assumptions!$C$56*12,E17)*12+('Cash Flow'!$I$21/0.08)*(1-Assumptions!$C$64)-(E17+CUMPRINC(Assumptions!$C$54/12,Assumptions!$C$56*12,E17,1,MIN(Assumptions!$C$62*12-Assumptions!$C$55,Assumptions!$C$56*12),0)) -> 95416.72
B34: 0.13 | C34: =IFERROR(IRR(N372:S372),"n/a") -> 0.69101472 | D34: =IFERROR(IRR(N373:S373),"n/a") -> 0.65126558 | E34: =IFERROR(IRR(N374:S374),"n/a") -> 0.61609197 | F34: =IFERROR(IRR(N375:S375),"n/a") -> 0.58453117 | G34: =IFERROR(IRR(N376:S376),"n/a") -> 0.55588641 | H34: =IFERROR(IRR(N377:S377),"n/a") -> 0.52963789 | I34: =IFERROR(IRR(N378:S378),"n/a") -> 0.50538787 | J34: =IFERROR(IRR(N379:S379),"n/a") -> 0.48282546 | K34: =IFERROR(IRR(N380:S380),"n/a") -> 0.46170312 | V34: ='Cash Flow'!$I$21+PMT(Assumptions!$C$54/12,Assumptions!$C$56*12,E18)*12+('Cash Flow'!$I$21/0.04)*(1-Assumptions!$C$64)-(E18+CUMPRINC(Assumptions!$C$54/12,Assumptions!$C$56*12,E18,1,MIN(Assumptions!$C$62*12-Assumptions!$C$55,Assumptions!$C$56*12),0)) -> 251723.95 | W34: ='Cash Flow'!$I$21+PMT(Assumptions!$C$54/12,Assumptions!$C$56*12,E18)*12+('Cash Flow'!$I$21/0.045)*(1-Assumptions!$C$64)-(E18+CUMPRINC(Assumptions!$C$54/12,Assumptions!$C$56*12,E18,1,MIN(Assumptions!$C$62*12-Assumptions!$C$55,Assumptions!$C$56*12),0)) -> 218151.28 | X34: ='Cash Flow'!$I$21+PMT(Assumptions!$C$54/12,Assumptions!$C$56*12,E18)*12+('Cash Flow'!$I$21/0.05)*(1-Assumptions!$C$64)-(E18+CUMPRINC(Assumptions!$C$54/12,Assumptions!$C$56*12,E18,1,MIN(Assumptions!$C$62*12-Assumptions!$C$55,Assumptions!$C$56*12),0)) -> 191293.15 | Y34: ='Cash Flow'!$I$21+PMT(Assumptions!$C$54/12,Assumptions!$C$56*12,E18)*12+('Cash Flow'!$I$21/0.055)*(1-Assumptions!$C$64)-(E18+CUMPRINC(Assumptions!$C$54/12,Assumptions!$C$56*12,E18,1,MIN(Assumptions!$C$62*12-Assumptions!$C$55,Assumptions!$C$56*12),0)) -> 169318.32 | Z34: ='Cash Flow'!$I$21+PMT(Assumptions!$C$54/12,Assumptions!$C$56*12,E18)*12+('Cash Flow'!$I$21/0.06)*(1-Assumptions!$C$64)-(E18+CUMPRINC(Assumptions!$C$54/12,Assumptions!$C$56*12,E18,1,MIN(Assumptions!$C$62*12-Assumptions!$C$55,Assumptions!$C$56*12),0)) -> 151005.95 | AA34: ='Cash Flow'!$I$21+PMT(Assumptions!$C$54/12,Assumptions!$C$56*12,E18)*12+('Cash Flow'!$I$21/0.065)*(1-Assumptions!$C$64)-(E18+CUMPRINC(Assumptions!$C$54/12,Assumptions!$C$56*12,E18,1,MIN(Assumptions!$C$62*12-Assumptions!$C$55,Assumptions!$C$56*12),0)) -> 135510.88 | AB34: ='Cash Flow'!$I$21+PMT(Assumptions!$C$54/12,Assumptions!$C$56*12,E18)*12+('Cash Flow'!$I$21/0.07)*(1-Assumptions!$C$64)-(E18+CUMPRINC(Assumptions!$C$54/12,Assumptions!$C$56*12,E18,1,MIN(Assumptions!$C$62*12-Assumptions!$C$55,Assumptions!$C$56*12),0)) -> 122229.38 | AC34: ='Cash Flow'!$I$21+PMT(Assumptions!$C$54/12,Assumptions!$C$56*12,E18)*12+('Cash Flow'!$I$21/0.075)*(1-Assumptions!$C$64)-(E18+CUMPRINC(Assumptions!$C$54/12,Assumptions!$C$56*12,E18,1,MIN(Assumptions!$C$62*12-Assumptions!$C$55,Assumptions!$C$56*12),0)) -> 110718.76 | AD34: ='Cash Flow'!$I$21+PMT(Assumptions!$C$54/12,Assumptions!$C$56*12,E18)*12+('Cash Flow'!$I$21/0.08)*(1-Assumptions!$C$64)-(E18+CUMPRINC(Assumptions!$C$54/12,Assumptions!$C$56*12,E18,1,MIN(Assumptions!$C$62*12-Assumptions!$C$55,Assumptions!$C$56*12),0)) -> 100646.96
